Workbook
Name A2A: 'Mata-Mata'!$B$2
Name D2A: 'Instruções'!$D$2

Sheet Instruções
A1: ⚽ COPA DO MUNDO FIFA 2026 · TABELA INTERATIVA | D1: Planilha criada por Edivaldo - Site https//www.tudoexcel.com.br
D2: Tudo Excel
B4: 🔵 COMO USAR
B5: 1. Preencha APENAS as células em azul (os placares dos jogos)
B6: 2. As classificações de cada grupo atualizam automaticamente | D6: Colaborador
B7: 3. Na aba '3os Lugares', os 8 melhores avançam (ranking automático) | D7: guiadecompra.com
B8: 4. Na aba 'Mata-Mata', os nomes dos classificados aparecem automaticamente | D8: Primeiro site a divulgar a tabela em Excel em 2006
B10: 📋 CRITÉRIOS DE DESEMPATE (Fase de Grupos) | D10: Hoje, cria reviews de produtos para você comprar os melhores e pelo melhor preço
B11: 1º Pontos | 2º Saldo de gols | 3º Gols marcados | 4º Confronto direto (verificar manualmente)
B13: ⚽ MATA-MATA — COMO PREENCHER | D13: guiadecompra.com
B14: • Se um jogo terminar EMPATADO no tempo normal: preencha Prorrogação (células amarelas)
B15: • Se o placar continuar empatado após a prorrogação: preencha Pênaltis (células laranja)
B16: • A coluna 'Classificado' atualiza automaticamente em cada fase
B18: 📅 DATAS
B19: Fase de Grupos: 11 a 27 de junho
B20: Rodada de 32: 28 jun – 3 jul
B21: Oitavas: 4 – 7 de julho
B22: Quartas: 9 – 11 de julho
B23: Semifinais: 14 – 15 de julho
B24: 3º Lugar: 18 de julho (Miami)
B25: FINAL: 19 de julho (MetLife Stadium, Nova York)
B27: ⚠️ NOTA SOBRE O CHAVEAMENTO
... B30: Os slots de 3os colocados dependem de quais grupos classificam para cada vaga.

Sheet Gr-A
A1: COPA DO MUNDO FIFA 2026 · GRUPO A
A3: ▶ JOGOS DA FASE DE GRUPOS (preencha apenas os placares em azul)
A4: Rodada | B4: Mandante | D4: GD | F4: GV | H4: Visitante | I4: Local
A5: 11/06 # 16h | B5: =Q5 -> México | D5: 2 | E5: ✕ | F5: 0 | H5: =Q6 -> África do Sul | I5: Cidade do México | M5: NAVEGUE PELOS GRUPOS | Q5: México
A6: 11/06 # 23h | B6: =Q7 -> Coreia do Sul | D6: 2 | E6: ✕ | F6: 1 | H6: =Q8 -> República Tcheca | I6: Guadalajara | M6: A | N6: B | O6: C | P6: D | Q6: África do Sul
A7: 18/06 # 13h | B7: =Q8 -> República Tcheca | D7: 1 | E7: ✕ | F7: 1 | H7: =Q6 -> África do Sul | I7: Atlanta | M7: E | N7: F | O7: G | P7: H | Q7: Coreia do Sul
A8: 18/06 # 22h | B8: =Q5 -> México | D8: 1 | E8: ✕ | F8: 0 | H8: =Q7 -> Coreia do Sul | I8: Guadalajara | M8: I | N8: J | O8: K | P8: L | Q8: República Tcheca
A9: 24/06 # 22h | B9: =Q8 -> República Tcheca | E9: ✕ | H9: =Q5 -> México | I9: Cidade do México
A10: 24/06 # 22h | B10: =Q6 -> África do Sul | E10: ✕ | H10: =Q7 -> Coreia do Sul | I10: Monterrey | M10: Tudo Excel
A12: ▶ CLASSIFICAÇÃO (atualização automática)
A13: Pos | B13: Seleção | I13: J | J13: V | K13: E | L13: D | M13: GP | N13: GC | O13: SG | P13: PTS
A14: 1 | B14: {=INDEX(Q$14:Q$17,MATCH(1,AA$14:AA$17,0))} -> México | I14: {=INDEX(R$14:R$17,MATCH(1,AA$14:AA$17,0))} -> 2 | J14: {=INDEX(S$14:S$17,MATCH(1,AA$14:AA$17,0))} -> 2 | K14: {=INDEX(T$14:T$17,MATCH(1,AA$14:AA$17,0))} -> 0 | L14: {=INDEX(U$14:U$17,MATCH(1,AA$14:AA$17,0))} -> 0 | M14: {=INDEX(V$14:V$17,MATCH(1,AA$14:AA$17,0))} -> 3 | N14: {=INDEX(W$14:W$17,MATCH(1,AA$14:AA$17,0))} -> 0 | O14: {=INDEX(X$14:X$17,MATCH(1,AA$14:AA$17,0))} -> 3 | P14: {=INDEX(Y$14:Y$17,MATCH(1,AA$14:AA$17,0))} -> 6 | Q14: =Q5 -> México | R14: =((D5<>"")*( F5<>""))+((D8<>"")*( F8<>""))+((D9<>"")*( F9<>"")) -> 2 | S14: =IF(AND(D5<>"",F5<>""),IF(D5>F5,1,0),0)+IF(AND(D8<>"",F8<>""),IF(D8>F8,1,0),0)+IF(AND(D9<>"",F9<>""),IF(F9>D9,1,0),0) -> 2 | T14: =IF(AND(D5<>"",F5<>""),IF(D5=F5,1,0),0)+IF(AND(D8<>"",F8<>""),IF(D8=F8,1,0),0)+IF(AND(D9<>"",F9<>""),IF(D9=F9,1,0),0) -> 0 | U14: =IF(AND(D5<>"",F5<>""),IF(D5<F5,1,0),0)+IF(AND(D8<>"",F8<>""),IF(D8<F8,1,0),0)+IF(AND(D9<>"",F9<>""),IF(F9<D9,1,0),0) -> 0 | V14: =IF(D5="",0,D5)+IF(D8="",0,D8)+IF(F9="",0,F9) -> 3 | W14: =IF(F5="",0,F5)+IF(F8="",0,F8)+IF(D9="",0,D9) -> 0 | X14: =V14-W14 -> 3 | Y14: =S14*3+T14 -> 6 | Z14: =Y14*1000000+(X14+100)*10000+V14*100+4 -> 7030304 | AA14: =RANK(Z14,Z$14:Z$17,0) -> 1
A15: 2 | B15: {=INDEX(Q$14:Q$17,MATCH(2,AA$14:AA$17,0))} -> Coreia do Sul | I15: {=INDEX(R$14:R$17,MATCH(2,AA$14:AA$17,0))} -> 2 | J15: {=INDEX(S$14:S$17,MATCH(2,AA$14:AA$17,0))} -> 1 | K15: {=INDEX(T$14:T$17,MATCH(2,AA$14:AA$17,0))} -> 0 | L15: {=INDEX(U$14:U$17,MATCH(2,AA$14:AA$17,0))} -> 1 | M15: {=INDEX(V$14:V$17,MATCH(2,AA$14:AA$17,0))} -> 2 | N15: {=INDEX(W$14:W$17,MATCH(2,AA$14:AA$17,0))} -> 2 | O15: {=INDEX(X$14:X$17,MATCH(2,AA$14:AA$17,0))} -> 0 | P15: {=INDEX(Y$14:Y$17,MATCH(2,AA$14:AA$17,0))} -> 3 | Q15: =Q6 -> África do Sul | R15: =((D5<>"")*( F5<>""))+((D7<>"")*( F7<>""))+((D10<>"")*( F10<>"")) -> 2 | S15: =IF(AND(D5<>"",F5<>""),IF(F5>D5,1,0),0)+IF(AND(D7<>"",F7<>""),IF(F7>D7,1,0),0)+IF(AND(D10<>"",F10<>""),IF(D10>F10,1,0),0) -> 0 | T15: =IF(AND(D5<>"",F5<>""),IF(D5=F5,1,0),0)+IF(AND(D7<>"",F7<>""),IF(D7=F7,1,0),0)+IF(AND(D10<>"",F10<>""),IF(D10=F10,1,0),0) -> 1 | U15: =IF(AND(D5<>"",F5<>""),IF(F5<D5,1,0),0)+IF(AND(D7<>"",F7<>""),IF(F7<D7,1,0),0)+IF(AND(D10<>"",F10<>""),IF(D10<F10,1,0),0) -> 1 | V15: =IF(F5="",0,F5)+IF(F7="",0,F7)+IF(D10="",0,D10) -> 1 | W15: =IF(D5="",0,D5)+IF(D7="",0,D7)+IF(F10="",0,F10) -> 3 | X15: =V15-W15 -> -2 | Y15: =S15*3+T15 -> 1 | Z15: =Y15*1000000+(X15+100)*10000+V15*100+3 -> 1980103 | AA15: =RANK(Z15,Z$14:Z$17,0) -> 4
A16: 3 | B16: {=INDEX(Q$14:Q$17,MATCH(3,AA$14:AA$17,0))} -> República Tcheca | I16: {=INDEX(R$14:R$17,MATCH(3,AA$14:AA$17,0))} -> 2 | J16: {=INDEX(S$14:S$17,MATCH(3,AA$14:AA$17,0))} -> 0 | K16: {=INDEX(T$14:T$17,MATCH(3,AA$14:AA$17,0))} -> 1 | L16: {=INDEX(U$14:U$17,MATCH(3,AA$14:AA$17,0))} -> 1 | M16: {=INDEX(V$14:V$17,MATCH(3,AA$14:AA$17,0))} -> 2 | N16: {=INDEX(W$14:W$17,MATCH(3,AA$14:AA$17,0))} -> 3 | O16: {=INDEX(X$14:X$17,MATCH(3,AA$14:AA$17,0))} -> -1 | P16: {=INDEX(Y$14:Y$17,MATCH(3,AA$14:AA$17,0))} -> 1 | Q16: =Q7 -> Coreia do Sul | R16: =((D6<>"")*( F6<>""))+((D8<>"")*( F8<>""))+((D10<>"")*( F10<>"")) -> 2 | S16: =IF(AND(D6<>"",F6<>""),IF(D6>F6,1,0),0)+IF(AND(D8<>"",F8<>""),IF(F8>D8,1,0),0)+IF(AND(D10<>"",F10<>""),IF(F10>D10,1,0),0) -> 1 | T16: =IF(AND(D6<>"",F6<>""),IF(D6=F6,1,0),0)+IF(AND(D8<>"",F8<>""),IF(D8=F8,1,0),0)+IF(AND(D10<>"",F10<>""),IF(D10=F10,1,0),0) -> 0 | U16: =IF(AND(D6<>"",F6<>""),IF(D6<F6,1,0),0)+IF(AND(D8<>"",F8<>""),IF(F8<D8,1,0),0)+IF(AND(D10<>"",F10<>""),IF(F10<D10,1,0),0) -> 1 | V16: =IF(D6="",0,D6)+IF(F8="",0,F8)+IF(F10="",0,F10) -> 2 | W16: =IF(F6="",0,F6)+IF(D8="",0,D8)+IF(D10="",0,D10) -> 2 | X16: =V16-W16 -> 0 | Y16: =S16*3+T16 -> 3 | Z16: =Y16*1000000+(X16+100)*10000+V16*100+2 -> 4000202 | AA16: =RANK(Z16,Z$14:Z$17,0) -> 2
A17: 4 | B17: {=INDEX(Q$14:Q$17,MATCH(4,AA$14:AA$17,0))} -> África do Sul | I17: {=INDEX(R$14:R$17,MATCH(4,AA$14:AA$17,0))} -> 2 | J17: {=INDEX(S$14:S$17,MATCH(4,AA$14:AA$17,0))} -> 0 | K17: {=INDEX(T$14:T$17,MATCH(4,AA$14:AA$17,0))} -> 1 | L17: {=INDEX(U$14:U$17,MATCH(4,AA$14:AA$17,0))} -> 1 | M17: {=INDEX(V$14:V$17,MATCH(4,AA$14:AA$17,0))} -> 1 | N17: {=INDEX(W$14:W$17,MATCH(4,AA$14:AA$17,0))} -> 3 | O17: {=INDEX(X$14:X$17,MATCH(4,AA$14:AA$17,0))} -> -2 | P17: {=INDEX(Y$14:Y$17,MATCH(4,AA$14:AA$17,0))} -> 1 | Q17: =Q8 -> República Tcheca | R17: =((D6<>"")*( F6<>""))+((D7<>"")*( F7<>""))+((D9<>"")*( F9<>"")) -> 2 | S17: =IF(AND(D6<>"",F6<>""),IF(F6>D6,1,0),0)+IF(AND(D7<>"",F7<>""),IF(D7>F7,1,0),0)+IF(AND(D9<>"",F9<>""),IF(D9>F9,1,0),0) -> 0 | T17: =IF(AND(D6<>"",F6<>""),IF(D6=F6,1,0),0)+IF(AND(D7<>"",F7<>""),IF(D7=F7,1,0),0)+IF(AND(D9<>"",F9<>""),IF(D9=F9,1,0),0) -> 1 | U17: =IF(AND(D6<>"",F6<>""),IF(F6<D6,1,0),0)+IF(AND(D7<>"",F7<>""),IF(D7<F7,1,0),0)+IF(AND(D9<>"",F9<>""),IF(D9<F9,1,0),0) -> 1 | V17: =IF(F6="",0,F6)+IF(D7="",0,D7)+IF(D9="",0,D9) -> 2 | W17: =IF(D6="",0,D6)+IF(F7="",0,F7)+IF(F9="",0,F9) -> 3 | X17: =V17-W17 -> -1 | Y17: =S17*3+T17 -> 1 | Z17: =Y17*1000000+(X17+100)*10000+V17*100+1 -> 1990201 | AA17: =RANK(Z17,Z$14:Z$17,0) -> 3
A20: 🟢 1º e 2º classificados 🟡 3º colocado (pode avançar se for top-8) 🔴 Eliminado

Sheet Gr-B
A1: COPA DO MUNDO FIFA 2026 · GRUPO B
A3: ▶ JOGOS DA FASE DE GRUPOS (preencha apenas os placares em azul)
A4: Rodada | B4: Mandante | D4: GD | F4: GV | H4: Visitante | I4: Local
A5: 12/06 # 16h | B5: =Q5 -> Canadá | D5: 1 | E5: ✕ | F5: 1 | H5: =Q6 -> Bósnia-Herzegovina | I5: Toronto Field | M5: NAVEGUE PELOS GRUPOS | Q5: Canadá
A6: 13/06 # 16h | B6: =Q7 -> Catar | D6: 1 | E6: ✕ | F6: 1 | H6: =Q8 -> Suíça | I6: Santa Clara | M6: A | N6: B | O6: C | P6: D | Q6: Bósnia-Herzegovina
A7: 18/06 # 16h | B7: =Q8 -> Suíça | D7: 4 | E7: ✕ | F7: 1 | H7: =Q6 -> Bósnia-Herzegovina | I7: Los Angeles | M7: E | N7: F | O7: G | P7: H | Q7: Catar
A8: 18/06 # 19h | B8: =Q5 -> Canadá | D8: 6 | E8: ✕ | F8: 0 | H8: =Q7 -> Catar | I8: Vancouver | M8: I | N8: J | O8: K | P8: L | Q8: Suíça
A9: 24/06 # 16h | B9: =Q8 -> Suíça | E9: ✕ | H9: =Q5 -> Canadá | I9: Vancouver
A10: 24/06 # 16h | B10: =Q6 -> Bósnia-Herzegovina | E10: ✕ | H10: =Q7 -> Catar | I10: Seattle | M10: Tudo Excel
A12: ▶ CLASSIFICAÇÃO (atualização automática)
A13: Pos | B13: Seleção | I13: J | J13: V | K13: E | L13: D | M13: GP | N13: GC | O13: SG | P13: PTS
A14: 1 | B14: {=INDEX(Q$14:Q$17,MATCH(1,AA$14:AA$17,0))} -> Canadá | I14: {=INDEX(R$14:R$17,MATCH(1,AA$14:AA$17,0))} -> 2 | J14: {=INDEX(S$14:S$17,MATCH(1,AA$14:AA$17,0))} -> 1 | K14: {=INDEX(T$14:T$17,MATCH(1,AA$14:AA$17,0))} -> 1 | L14: {=INDEX(U$14:U$17,MATCH(1,AA$14:AA$17,0))} -> 0 | M14: {=INDEX(V$14:V$17,MATCH(1,AA$14:AA$17,0))} -> 7 | N14: {=INDEX(W$14:W$17,MATCH(1,AA$14:AA$17,0))} -> 1 | O14: {=INDEX(X$14:X$17,MATCH(1,AA$14:AA$17,0))} -> 6 | P14: {=INDEX(Y$14:Y$17,MATCH(1,AA$14:AA$17,0))} -> 4 | Q14: =Q5 -> Canadá | R14: =((D5<>"")*( F5<>""))+((D8<>"")*( F8<>""))+((D9<>"")*( F9<>"")) -> 2 | S14: =IF(AND(D5<>"",F5<>""),IF(D5>F5,1,0),0)+IF(AND(D8<>"",F8<>""),IF(D8>F8,1,0),0)+IF(AND(D9<>"",F9<>""),IF(F9>D9,1,0),0) -> 1 | T14: =IF(AND(D5<>"",F5<>""),IF(D5=F5,1,0),0)+IF(AND(D8<>"",F8<>""),IF(D8=F8,1,0),0)+IF(AND(D9<>"",F9<>""),IF(D9=F9,1,0),0) -> 1 | U14: =IF(AND(D5<>"",F5<>""),IF(D5<F5,1,0),0)+IF(AND(D8<>"",F8<>""),IF(D8<F8,1,0),0)+IF(AND(D9<>"",F9<>""),IF(F9<D9,1,0),0) -> 0 | V14: =IF(D5="",0,D5)+IF(D8="",0,D8)+IF(F9="",0,F9) -> 7 | W14: =IF(F5="",0,F5)+IF(F8="",0,F8)+IF(D9="",0,D9) -> 1 | X14: =V14-W14 -> 6 | Y14: =S14*3+T14 -> 4 | Z14: =Y14*1000000+(X14+100)*10000+V14*100+4 -> 5060704 | AA14: =RANK(Z14,Z$14:Z$17,0) -> 1
A15: 2 | B15: {=INDEX(Q$14:Q$17,MATCH(2,AA$14:AA$17,0))} -> Suíça | I15: {=INDEX(R$14:R$17,MATCH(2,AA$14:AA$17,0))} -> 2 | J15: {=INDEX(S$14:S$17,MATCH(2,AA$14:AA$17,0))} -> 1 | K15: {=INDEX(T$14:T$17,MATCH(2,AA$14:AA$17,0))} -> 1 | L15: {=INDEX(U$14:U$17,MATCH(2,AA$14:AA$17,0))} -> 0 | M15: {=INDEX(V$14:V$17,MATCH(2,AA$14:AA$17,0))} -> 5 | N15: {=INDEX(W$14:W$17,MATCH(2,AA$14:AA$17,0))} -> 2 | O15: {=INDEX(X$14:X$17,MATCH(2,AA$14:AA$17,0))} -> 3 | P15: {=INDEX(Y$14:Y$17,MATCH(2,AA$14:AA$17,0))} -> 4 | Q15: =Q6 -> Bósnia-Herzegovina | R15: =((D5<>"")*( F5<>""))+((D7<>"")*( F7<>""))+((D10<>"")*( F10<>"")) -> 2 | S15: =IF(AND(D5<>"",F5<>""),IF(F5>D5,1,0),0)+IF(AND(D7<>"",F7<>""),IF(F7>D7,1,0),0)+IF(AND(D10<>"",F10<>""),IF(D10>F10,1,0),0) -> 0 | T15: =IF(AND(D5<>"",F5<>""),IF(D5=F5,1,0),0)+IF(AND(D7<>"",F7<>""),IF(D7=F7,1,0),0)+IF(AND(D10<>"",F10<>""),IF(D10=F10,1,0),0) -> 1 | U15: =IF(AND(D5<>"",F5<>""),IF(F5<D5,1,0),0)+IF(AND(D7<>"",F7<>""),IF(F7<D7,1,0),0)+IF(AND(D10<>"",F10<>""),IF(D10<F10,1,0),0) -> 1 | V15: =IF(F5="",0,F5)+IF(F7="",0,F7)+IF(D10="",0,D10) -> 2 | W15: =IF(D5="",0,D5)+IF(D7="",0,D7)+IF(F10="",0,F10) -> 5 | X15: =V15-W15 -> -3 | Y15: =S15*3+T15 -> 1 | Z15: =Y15*1000000+(X15+100)*10000+V15*100+3 -> 1970203 | AA15: =RANK(Z15,Z$14:Z$17,0) -> 3
A16: 3 | B16: {=INDEX(Q$14:Q$17,MATCH(3,AA$14:AA$17,0))} -> Bósnia-Herzegovina | I16: {=INDEX(R$14:R$17,MATCH(3,AA$14:AA$17,0))} -> 2 | J16: {=INDEX(S$14:S$17,MATCH(3,AA$14:AA$17,0))} -> 0 | K16: {=INDEX(T$14:T$17,MATCH(3,AA$14:AA$17,0))} -> 1 | L16: {=INDEX(U$14:U$17,MATCH(3,AA$14:AA$17,0))} -> 1 | M16: {=INDEX(V$14:V$17,MATCH(3,AA$14:AA$17,0))} -> 2 | N16: {=INDEX(W$14:W$17,MATCH(3,AA$14:AA$17,0))} -> 5 | O16: {=INDEX(X$14:X$17,MATCH(3,AA$14:AA$17,0))} -> -3 | P16: {=INDEX(Y$14:Y$17,MATCH(3,AA$14:AA$17,0))} -> 1 | Q16: =Q7 -> Catar | R16: =((D6<>"")*( F6<>""))+((D8<>"")*( F8<>""))+((D10<>"")*( F10<>"")) -> 2 | S16: =IF(AND(D6<>"",F6<>""),IF(D6>F6,1,0),0)+IF(AND(D8<>"",F8<>""),IF(F8>D8,1,0),0)+IF(AND(D10<>"",F10<>""),IF(F10>D10,1,0),0) -> 0 | T16: =IF(AND(D6<>"",F6<>""),IF(D6=F6,1,0),0)+IF(AND(D8<>"",F8<>""),IF(D8=F8,1,0),0)+IF(AND(D10<>"",F10<>""),IF(D10=F10,1,0),0) -> 1 | U16: =IF(AND(D6<>"",F6<>""),IF(D6<F6,1,0),0)+IF(AND(D8<>"",F8<>""),IF(F8<D8,1,0),0)+IF(AND(D10<>"",F10<>""),IF(F10<D10,1,0),0) -> 1 | V16: =IF(D6="",0,D6)+IF(F8="",0,F8)+IF(F10="",0,F10) -> 1 | W16: =IF(F6="",0,F6)+IF(D8="",0,D8)+IF(D10="",0,D10) -> 7 | X16: =V16-W16 -> -6 | Y16: =S16*3+T16 -> 1 | Z16: =Y16*1000000+(X16+100)*10000+V16*100+2 -> 1940102 | AA16: =RANK(Z16,Z$14:Z$17,0) -> 4
A17: 4 | B17: {=INDEX(Q$14:Q$17,MATCH(4,AA$14:AA$17,0))} -> Catar | I17: {=INDEX(R$14:R$17,MATCH(4,AA$14:AA$17,0))} -> 2 | J17: {=INDEX(S$14:S$17,MATCH(4,AA$14:AA$17,0))} -> 0 | K17: {=INDEX(T$14:T$17,MATCH(4,AA$14:AA$17,0))} -> 1 | L17: {=INDEX(U$14:U$17,MATCH(4,AA$14:AA$17,0))} -> 1 | M17: {=INDEX(V$14:V$17,MATCH(4,AA$14:AA$17,0))} -> 1 | N17: {=INDEX(W$14:W$17,MATCH(4,AA$14:AA$17,0))} -> 7 | O17: {=INDEX(X$14:X$17,MATCH(4,AA$14:AA$17,0))} -> -6 | P17: {=INDEX(Y$14:Y$17,MATCH(4,AA$14:AA$17,0))} -> 1 | Q17: =Q8 -> Suíça | R17: =((D6<>"")*( F6<>""))+((D7<>"")*( F7<>""))+((D9<>"")*( F9<>"")) -> 2 | S17: =IF(AND(D6<>"",F6<>""),IF(F6>D6,1,0),0)+IF(AND(D7<>"",F7<>""),IF(D7>F7,1,0),0)+IF(AND(D9<>"",F9<>""),IF(D9>F9,1,0),0) -> 1 | T17: =IF(AND(D6<>"",F6<>""),IF(D6=F6,1,0),0)+IF(AND(D7<>"",F7<>""),IF(D7=F7,1,0),0)+IF(AND(D9<>"",F9<>""),IF(D9=F9,1,0),0) -> 1 | U17: =IF(AND(D6<>"",F6<>""),IF(F6<D6,1,0),0)+IF(AND(D7<>"",F7<>""),IF(D7<F7,1,0),0)+IF(AND(D9<>"",F9<>""),IF(D9<F9,1,0),0) -> 0 | V17: =IF(F6="",0,F6)+IF(D7="",0,D7)+IF(D9="",0,D9) -> 5 | W17: =IF(D6="",0,D6)+IF(F7="",0,F7)+IF(F9="",0,F9) -> 2 | X17: =V17-W17 -> 3 | Y17: =S17*3+T17 -> 4 | Z17: =Y17*1000000+(X17+100)*10000+V17*100+1 -> 5030501 | AA17: =RANK(Z17,Z$14:Z$17,0) -> 2
A20: 🟢 1º e 2º classificados 🟡 3º colocado (pode avançar se for top-8) 🔴 Eliminado

Sheet Gr-C
A1: COPA DO MUNDO FIFA 2026 · GRUPO C
A3: ▶ JOGOS DA FASE DE GRUPOS (preencha apenas os placares em azul)
A4: Rodada | B4: Mandante | D4: GD | F4: GV | H4: Visitante | I4: Local
A5: 13/06 # 19h | B5: =Q5 -> Brasil | D5: 1 | E5: ✕ | F5: 1 | H5: =Q6 -> Marrocos | I5: Nova Jersey | M5: NAVEGUE PELOS GRUPOS | Q5: Brasil
A6: 13/06 # 22h | B6: =Q7 -> Haiti | D6: 0 | E6: ✕ | F6: 1 | H6: =Q8 -> Escócia | I6: Boston | M6: A | N6: B | O6: C | P6: D | Q6: Marrocos
A7: 19/06 # 19h | B7: =Q8 -> Escócia | D7: 0 | E7: ✕ | F7: 1 | H7: =Q6 -> Marrocos | I7: Boston | M7: E | N7: F | O7: G | P7: H | Q7: Haiti
A8: 19/06 # 22h | B8: =Q5 -> Brasil | D8: 3 | E8: ✕ | F8: 0 | H8: =Q7 -> Haiti | I8: Filadélfia | M8: I | N8: J | O8: K | P8: L | Q8: Escócia
A9: 24/06 # 19h | B9: =Q6 -> Marrocos | E9: ✕ | H9: =Q7 -> Haiti | I9: Atlanta
A10: 24/06 # 19h | B10: =Q8 -> Escócia | E10: ✕ | H10: =Q5 -> Brasil | I10: Miami | M10: Tudo Excel
A12: ▶ CLASSIFICAÇÃO (atualização automática)
A13: Pos | B13: Seleção | I13: J | J13: V | K13: E | L13: D | M13: GP | N13: GC | O13: SG | P13: PTS
A14: 1 | B14: {=INDEX(Q$14:Q$17,MATCH(1,AA$14:AA$17,0))} -> Brasil | I14: {=INDEX(R$14:R$17,MATCH(1,AA$14:AA$17,0))} -> 2 | J14: {=INDEX(S$14:S$17,MATCH(1,AA$14:AA$17,0))} -> 1 | K14: {=INDEX(T$14:T$17,MATCH(1,AA$14:AA$17,0))} -> 1 | L14: {=INDEX(U$14:U$17,MATCH(1,AA$14:AA$17,0))} -> 0 | M14: {=INDEX(V$14:V$17,MATCH(1,AA$14:AA$17,0))} -> 4 | N14: {=INDEX(W$14:W$17,MATCH(1,AA$14:AA$17,0))} -> 1 | O14: {=INDEX(X$14:X$17,MATCH(1,AA$14:AA$17,0))} -> 3 | P14: {=INDEX(Y$14:Y$17,MATCH(1,AA$14:AA$17,0))} -> 4 | Q14: =Q5 -> Brasil | R14: =((D5<>"")*( F5<>""))+((D8<>"")*( F8<>""))+((D10<>"")*( F10<>"")) -> 2 | S14: =IF(AND(D5<>"",F5<>""),IF(D5>F5,1,0),0)+IF(AND(D8<>"",F8<>""),IF(D8>F8,1,0),0)+IF(AND(D10<>"",F10<>""),IF(F10>D10,1,0),0) -> 1 | T14: =IF(AND(D5<>"",F5<>""),IF(D5=F5,1,0),0)+IF(AND(D8<>"",F8<>""),IF(D8=F8,1,0),0)+IF(AND(D10<>"",F10<>""),IF(D10=F10,1,0),0) -> 1 | U14: =IF(AND(D5<>"",F5<>""),IF(D5<F5,1,0),0)+IF(AND(D8<>"",F8<>""),IF(D8<F8,1,0),0)+IF(AND(D10<>"",F10<>""),IF(F10<D10,1,0),0) -> 0 | V14: =IF(D5="",0,D5)+IF(D8="",0,D8)+IF(F10="",0,F10) -> 4 | W14: =IF(F5="",0,F5)+IF(F8="",0,F8)+IF(D10="",0,D10) -> 1 | X14: =V14-W14 -> 3 | Y14: =S14*3+T14 -> 4 | Z14: =Y14*1000000+(X14+100)*10000+V14*100+4 -> 5030404 | AA14: =RANK(Z14,Z$14:Z$17,0) -> 1
A15: 2 | B15: {=INDEX(Q$14:Q$17,MATCH(2,AA$14:AA$17,0))} -> Marrocos | I15: {=INDEX(R$14:R$17,MATCH(2,AA$14:AA$17,0))} -> 2 | J15: {=INDEX(S$14:S$17,MATCH(2,AA$14:AA$17,0))} -> 1 | K15: {=INDEX(T$14:T$17,MATCH(2,AA$14:AA$17,0))} -> 1 | L15: {=INDEX(U$14:U$17,MATCH(2,AA$14:AA$17,0))} -> 0 | M15: {=INDEX(V$14:V$17,MATCH(2,AA$14:AA$17,0))} -> 2 | N15: {=INDEX(W$14:W$17,MATCH(2,AA$14:AA$17,0))} -> 1 | O15: {=INDEX(X$14:X$17,MATCH(2,AA$14:AA$17,0))} -> 1 | P15: {=INDEX(Y$14:Y$17,MATCH(2,AA$14:AA$17,0))} -> 4 | Q15: =Q6 -> Marrocos | R15: =((D5<>"")*( F5<>""))+((D7<>"")*( F7<>""))+((D9<>"")*( F9<>"")) -> 2 | S15: =IF(AND(D5<>"",F5<>""),IF(F5>D5,1,0),0)+IF(AND(D7<>"",F7<>""),IF(F7>D7,1,0),0)+IF(AND(D9<>"",F9<>""),IF(D9>F9,1,0),0) -> 1 | T15: =IF(AND(D5<>"",F5<>""),IF(D5=F5,1,0),0)+IF(AND(D7<>"",F7<>""),IF(D7=F7,1,0),0)+IF(AND(D9<>"",F9<>""),IF(D9=F9,1,0),0) -> 1 | U15: =IF(AND(D5<>"",F5<>""),IF(F5<D5,1,0),0)+IF(AND(D7<>"",F7<>""),IF(F7<D7,1,0),0)+IF(AND(D9<>"",F9<>""),IF(D9<F9,1,0),0) -> 0 | V15: =IF(F5="",0,F5)+IF(F7="",0,F7)+IF(D9="",0,D9) -> 2 | W15: =IF(D5="",0,D5)+IF(D7="",0,D7)+IF(F9="",0,F9) -> 1 | X15: =V15-W15 -> 1 | Y15: =S15*3+T15 -> 4 | Z15: =Y15*1000000+(X15+100)*10000+V15*100+3 -> 5010203 | AA15: =RANK(Z15,Z$14:Z$17,0) -> 2
A16: 3 | B16: {=INDEX(Q$14:Q$17,MATCH(3,AA$14:AA$17,0))} -> Escócia | I16: {=INDEX(R$14:R$17,MATCH(3,AA$14:AA$17,0))} -> 2 | J16: {=INDEX(S$14:S$17,MATCH(3,AA$14:AA$17,0))} -> 1 | K16: {=INDEX(T$14:T$17,MATCH(3,AA$14:AA$17,0))} -> 0 | L16: {=INDEX(U$14:U$17,MATCH(3,AA$14:AA$17,0))} -> 1 | M16: {=INDEX(V$14:V$17,MATCH(3,AA$14:AA$17,0))} -> 1 | N16: {=INDEX(W$14:W$17,MATCH(3,AA$14:AA$17,0))} -> 1 | O16: {=INDEX(X$14:X$17,MATCH(3,AA$14:AA$17,0))} -> 0 | P16: {=INDEX(Y$14:Y$17,MATCH(3,AA$14:AA$17,0))} -> 3 | Q16: =Q7 -> Haiti | R16: =((D6<>"")*( F6<>""))+((D8<>"")*( F8<>""))+((D9<>"")*( F9<>"")) -> 2 | S16: =IF(AND(D6<>"",F6<>""),IF(D6>F6,1,0),0)+IF(AND(D8<>"",F8<>""),IF(F8>D8,1,0),0)+IF(AND(D9<>"",F9<>""),IF(F9>D9,1,0),0) -> 0 | T16: =IF(AND(D6<>"",F6<>""),IF(D6=F6,1,0),0)+IF(AND(D8<>"",F8<>""),IF(D8=F8,1,0),0)+IF(AND(D9<>"",F9<>""),IF(D9=F9,1,0),0) -> 0 | U16: =IF(AND(D6<>"",F6<>""),IF(D6<F6,1,0),0)+IF(AND(D8<>"",F8<>""),IF(F8<D8,1,0),0)+IF(AND(D9<>"",F9<>""),IF(F9<D9,1,0),0) -> 2 | V16: =IF(D6="",0,D6)+IF(F8="",0,F8)+IF(F9="",0,F9) -> 0 | W16: =IF(F6="",0,F6)+IF(D8="",0,D8)+IF(D9="",0,D9) -> 4 | X16: =V16-W16 -> -4 | Y16: =S16*3+T16 -> 0 | Z16: =Y16*1000000+(X16+100)*10000+V16*100+2 -> 960002 | AA16: =RANK(Z16,Z$14:Z$17,0) -> 4
A17: 4 | B17: {=INDEX(Q$14:Q$17,MATCH(4,AA$14:AA$17,0))} -> Haiti | I17: {=INDEX(R$14:R$17,MATCH(4,AA$14:AA$17,0))} -> 2 | J17: {=INDEX(S$14:S$17,MATCH(4,AA$14:AA$17,0))} -> 0 | K17: {=INDEX(T$14:T$17,MATCH(4,AA$14:AA$17,0))} -> 0 | L17: {=INDEX(U$14:U$17,MATCH(4,AA$14:AA$17,0))} -> 2 | M17: {=INDEX(V$14:V$17,MATCH(4,AA$14:AA$17,0))} -> 0 | N17: {=INDEX(W$14:W$17,MATCH(4,AA$14:AA$17,0))} -> 4 | O17: {=INDEX(X$14:X$17,MATCH(4,AA$14:AA$17,0))} -> -4 | P17: {=INDEX(Y$14:Y$17,MATCH(4,AA$14:AA$17,0))} -> 0 | Q17: =Q8 -> Escócia | R17: =((D6<>"")*( F6<>""))+((D7<>"")*( F7<>""))+((D10<>"")*( F10<>"")) -> 2 | S17: =IF(AND(D6<>"",F6<>""),IF(F6>D6,1,0),0)+IF(AND(D7<>"",F7<>""),IF(D7>F7,1,0),0)+IF(AND(D10<>"",F10<>""),IF(D10>F10,1,0),0) -> 1 | T17: =IF(AND(D6<>"",F6<>""),IF(D6=F6,1,0),0)+IF(AND(D7<>"",F7<>""),IF(D7=F7,1,0),0)+IF(AND(D10<>"",F10<>""),IF(D10=F10,1,0),0) -> 0 | U17: =IF(AND(D6<>"",F6<>""),IF(F6<D6,1,0),0)+IF(AND(D7<>"",F7<>""),IF(D7<F7,1,0),0)+IF(AND(D10<>"",F10<>""),IF(D10<F10,1,0),0) -> 1 | V17: =IF(F6="",0,F6)+IF(D7="",0,D7)+IF(D10="",0,D10) -> 1 | W17: =IF(D6="",0,D6)+IF(F7="",0,F7)+IF(F10="",0,F10) -> 1 | X17: =V17-W17 -> 0 | Y17: =S17*3+T17 -> 3 | Z17: =Y17*1000000+(X17+100)*10000+V17*100+1 -> 4000101 | AA17: =RANK(Z17,Z$14:Z$17,0) -> 3
A20: 🟢 1º e 2º classificados 🟡 3º colocado (pode avançar se for top-8) 🔴 Eliminado

Sheet Gr-D
A1: COPA DO MUNDO FIFA 2026 · GRUPO D
A3: ▶ JOGOS DA FASE DE GRUPOS (preencha apenas os placares em azul)
A4: Rodada | B4: Mandante | D4: GD | F4: GV | H4: Visitante | I4: Local
A5: 12/06 # 22h | B5: =Q5 -> Estados Unidos | D5: 4 | E5: ✕ | F5: 1 | H5: =Q6 -> Paraguai | I5: Los Angeles | M5: NAVEGUE PELOS GRUPOS | Q5: Estados Unidos
A6: 14/06 # 01h | B6: =Q7 -> Austrália | D6: 2 | E6: ✕ | F6: 0 | H6: =Q8 -> Turquia | I6: Vancouver Place | M6: A | N6: B | O6: C | P6: D | Q6: Paraguai
A7: 19/06 # 16h | B7: =Q5 -> Estados Unidos | D7: 2 | E7: ✕ | F7: 0 | H7: =Q7 -> Austrália | I7: Seattle | M7: E | N7: F | O7: G | P7: H | Q7: Austrália
A8: 20/06 # 01h | B8: =Q8 -> Turquia | D8: 0 | E8: ✕ | F8: 1 | H8: =Q6 -> Paraguai | I8: São Francisco | M8: I | N8: J | O8: K | P8: L | Q8: Turquia
A9: 25/06 # 23h | B9: =Q8 -> Turquia | E9: ✕ | H9: =Q5 -> Estados Unidos | I9: Los Angeles
A10: 25/06 # 23h | B10: =Q6 -> Paraguai | E10: ✕ | H10: =Q7 -> Austrália | I10: São Francisco | M10: Tudo Excel
A12: ▶ CLASSIFICAÇÃO (atualização automática)
A13: Pos | B13: Seleção | I13: J | J13: V | K13: E | L13: D | M13: GP | N13: GC | O13: SG | P13: PTS
A14: 1 | B14: {=INDEX(Q$14:Q$17,MATCH(1,AA$14:AA$17,0))} -> Estados Unidos | I14: {=INDEX(R$14:R$17,MATCH(1,AA$14:AA$17,0))} -> 2 | J14: {=INDEX(S$14:S$17,MATCH(1,AA$14:AA$17,0))} -> 2 | K14: {=INDEX(T$14:T$17,MATCH(1,AA$14:AA$17,0))} -> 0 | L14: {=INDEX(U$14:U$17,MATCH(1,AA$14:AA$17,0))} -> 0 | M14: {=INDEX(V$14:V$17,MATCH(1,AA$14:AA$17,0))} -> 6 | N14: {=INDEX(W$14:W$17,MATCH(1,AA$14:AA$17,0))} -> 1 | O14: {=INDEX(X$14:X$17,MATCH(1,AA$14:AA$17,0))} -> 5 | P14: {=INDEX(Y$14:Y$17,MATCH(1,AA$14:AA$17,0))} -> 6 | Q14: =Q5 -> Estados Unidos | R14: =((D5<>"")*( F5<>""))+((D7<>"")*( F7<>""))+((D9<>"")*( F9<>"")) -> 2 | S14: =IF(AND(D5<>"",F5<>""),IF(D5>F5,1,0),0)+IF(AND(D7<>"",F7<>""),IF(D7>F7,1,0),0)+IF(AND(D9<>"",F9<>""),IF(F9>D9,1,0),0) -> 2 | T14: =IF(AND(D5<>"",F5<>""),IF(D5=F5,1,0),0)+IF(AND(D7<>"",F7<>""),IF(D7=F7,1,0),0)+IF(AND(D9<>"",F9<>""),IF(D9=F9,1,0),0) -> 0 | U14: =IF(AND(D5<>"",F5<>""),IF(D5<F5,1,0),0)+IF(AND(D7<>"",F7<>""),IF(D7<F7,1,0),0)+IF(AND(D9<>"",F9<>""),IF(F9<D9,1,0),0) -> 0 | V14: =IF(D5="",0,D5)+IF(D7="",0,D7)+IF(F9="",0,F9) -> 6 | W14: =IF(F5="",0,F5)+IF(F7="",0,F7)+IF(D9="",0,D9) -> 1 | X14: =V14-W14 -> 5 | Y14: =S14*3+T14 -> 6 | Z14: =Y14*1000000+(X14+100)*10000+V14*100+4 -> 7050604 | AA14: =RANK(Z14,Z$14:Z$17,0) -> 1
A15: 2 | B15: {=INDEX(Q$14:Q$17,MATCH(2,AA$14:AA$17,0))} -> Austrália | I15: {=INDEX(R$14:R$17,MATCH(2,AA$14:AA$17,0))} -> 2 | J15: {=INDEX(S$14:S$17,MATCH(2,AA$14:AA$17,0))} -> 1 | K15: {=INDEX(T$14:T$17,MATCH(2,AA$14:AA$17,0))} -> 0 | L15: {=INDEX(U$14:U$17,MATCH(2,AA$14:AA$17,0))} -> 1 | M15: {=INDEX(V$14:V$17,MATCH(2,AA$14:AA$17,0))} -> 2 | N15: {=INDEX(W$14:W$17,MATCH(2,AA$14:AA$17,0))} -> 2 | O15: {=INDEX(X$14:X$17,MATCH(2,AA$14:AA$17,0))} -> 0 | P15: {=INDEX(Y$14:Y$17,MATCH(2,AA$14:AA$17,0))} -> 3 | Q15: =Q6 -> Paraguai | R15: =((D5<>"")*( F5<>""))+((D8<>"")*( F8<>""))+((D10<>"")*( F10<>"")) -> 2 | S15: =IF(AND(D5<>"",F5<>""),IF(F5>D5,1,0),0)+IF(AND(D8<>"",F8<>""),IF(F8>D8,1,0),0)+IF(AND(D10<>"",F10<>""),IF(D10>F10,1,0),0) -> 1 | T15: =IF(AND(D5<>"",F5<>""),IF(D5=F5,1,0),0)+IF(AND(D8<>"",F8<>""),IF(D8=F8,1,0),0)+IF(AND(D10<>"",F10<>""),IF(D10=F10,1,0),0) -> 0 | U15: =IF(AND(D5<>"",F5<>""),IF(F5<D5,1,0),0)+IF(AND(D8<>"",F8<>""),IF(F8<D8,1,0),0)+IF(AND(D10<>"",F10<>""),IF(D10<F10,1,0),0) -> 1 | V15: =IF(F5="",0,F5)+IF(F8="",0,F8)+IF(D10="",0,D10) -> 2 | W15: =IF(D5="",0,D5)+IF(D8="",0,D8)+IF(F10="",0,F10) -> 4 | X15: =V15-W15 -> -2 | Y15: =S15*3+T15 -> 3 | Z15: =Y15*1000000+(X15+100)*10000+V15*100+3 -> 3980203 | AA15: =RANK(Z15,Z$14:Z$17,0) -> 3
A16: 3 | B16: {=INDEX(Q$14:Q$17,MATCH(3,AA$14:AA$17,0))} -> Paraguai | I16: {=INDEX(R$14:R$17,MATCH(3,AA$14:AA$17,0))} -> 2 | J16: {=INDEX(S$14:S$17,MATCH(3,AA$14:AA$17,0))} -> 1 | K16: {=INDEX(T$14:T$17,MATCH(3,AA$14:AA$17,0))} -> 0 | L16: {=INDEX(U$14:U$17,MATCH(3,AA$14:AA$17,0))} -> 1 | M16: {=INDEX(V$14:V$17,MATCH(3,AA$14:AA$17,0))} -> 2 | N16: {=INDEX(W$14:W$17,MATCH(3,AA$14:AA$17,0))} -> 4 | O16: {=INDEX(X$14:X$17,MATCH(3,AA$14:AA$17,0))} -> -2 | P16: {=INDEX(Y$14:Y$17,MATCH(3,AA$14:AA$17,0))} -> 3 | Q16: =Q7 -> Austrália | R16: =((D6<>"")*( F6<>""))+((D7<>"")*( F7<>""))+((D10<>"")*( F10<>"")) -> 2 | S16: =IF(AND(D6<>"",F6<>""),IF(D6>F6,1,0),0)+IF(AND(D7<>"",F7<>""),IF(F7>D7,1,0),0)+IF(AND(D10<>"",F10<>""),IF(F10>D10,1,0),0) -> 1 | T16: =IF(AND(D6<>"",F6<>""),IF(D6=F6,1,0),0)+IF(AND(D7<>"",F7<>""),IF(D7=F7,1,0),0)+IF(AND(D10<>"",F10<>""),IF(D10=F10,1,0),0) -> 0 | U16: =IF(AND(D6<>"",F6<>""),IF(D6<F6,1,0),0)+IF(AND(D7<>"",F7<>""),IF(F7<D7,1,0),0)+IF(AND(D10<>"",F10<>""),IF(F10<D10,1,0),0) -> 1 | V16: =IF(D6="",0,D6)+IF(F7="",0,F7)+IF(F10="",0,F10) -> 2 | W16: =IF(F6="",0,F6)+IF(D7="",0,D7)+IF(D10="",0,D10) -> 2 | X16: =V16-W16 -> 0 | Y16: =S16*3+T16 -> 3 | Z16: =Y16*1000000+(X16+100)*10000+V16*100+2 -> 4000202 | AA16: =RANK(Z16,Z$14:Z$17,0) -> 2
A17: 4 | B17: {=INDEX(Q$14:Q$17,MATCH(4,AA$14:AA$17,0))} -> Turquia | I17: {=INDEX(R$14:R$17,MATCH(4,AA$14:AA$17,0))} -> 2 | J17: {=INDEX(S$14:S$17,MATCH(4,AA$14:AA$17,0))} -> 0 | K17: {=INDEX(T$14:T$17,MATCH(4,AA$14:AA$17,0))} -> 0 | L17: {=INDEX(U$14:U$17,MATCH(4,AA$14:AA$17,0))} -> 2 | M17: {=INDEX(V$14:V$17,MATCH(4,AA$14:AA$17,0))} -> 0 | N17: {=INDEX(W$14:W$17,MATCH(4,AA$14:AA$17,0))} -> 3 | O17: {=INDEX(X$14:X$17,MATCH(4,AA$14:AA$17,0))} -> -3 | P17: {=INDEX(Y$14:Y$17,MATCH(4,AA$14:AA$17,0))} -> 0 | Q17: =Q8 -> Turquia | R17: =((D6<>"")*( F6<>""))+((D8<>"")*( F8<>""))+((D9<>"")*( F9<>"")) -> 2 | S17: =IF(AND(D6<>"",F6<>""),IF(F6>D6,1,0),0)+IF(AND(D8<>"",F8<>""),IF(D8>F8,1,0),0)+IF(AND(D9<>"",F9<>""),IF(D9>F9,1,0),0) -> 0 | T17: =IF(AND(D6<>"",F6<>""),IF(D6=F6,1,0),0)+IF(AND(D8<>"",F8<>""),IF(D8=F8,1,0),0)+IF(AND(D9<>"",F9<>""),IF(D9=F9,1,0),0) -> 0 | U17: =IF(AND(D6<>"",F6<>""),IF(F6<D6,1,0),0)+IF(AND(D8<>"",F8<>""),IF(D8<F8,1,0),0)+IF(AND(D9<>"",F9<>""),IF(D9<F9,1,0),0) -> 2 | V17: =IF(F6="",0,F6)+IF(D8="",0,D8)+IF(D9="",0,D9) -> 0 | W17: =IF(D6="",0,D6)+IF(F8="",0,F8)+IF(F9="",0,F9) -> 3 | X17: =V17-W17 -> -3 | Y17: =S17*3+T17 -> 0 | Z17: =Y17*1000000+(X17+100)*10000+V17*100+1 -> 970001 | AA17: =RANK(Z17,Z$14:Z$17,0) -> 4
A20: 🟢 1º e 2º classificados 🟡 3º colocado (pode avançar se for top-8) 🔴 Eliminado

Sheet Gr-E
A1: COPA DO MUNDO FIFA 2026 · GRUPO E
A3: ▶ JOGOS DA FASE DE GRUPOS (preencha apenas os placares em azul)
A4: Rodada | B4: Mandante | D4: GD | F4: GV | H4: Visitante | I4: Local
A5: 14/06 # 14h | B5: =Q5 -> Alemanha | D5: 7 | E5: ✕ | F5: 1 | H5: =Q6 -> Curaçao | I5: Houston | M5: NAVEGUE PELOS GRUPOS | Q5: Alemanha
A6: 14/06 # 20h | B6: =Q7 -> Costa do Marfim | D6: 1 | E6: ✕ | F6: 0 | H6: =Q8 -> Equador | I6: Filadélfia | M6: A | N6: B | O6: C | P6: D | Q6: Curaçao
A7: 20/06 # 17h | B7: =Q5 -> Alemanha | D7: 2 | E7: ✕ | F7: 1 | H7: =Q7 -> Costa do Marfim | I7: Toronto | M7: E | N7: F | O7: G | P7: H | Q7: Costa do Marfim
A8: 20/06 # 21h | B8: =Q8 -> Equador | D8: 0 | E8: ✕ | F8: 0 | H8: =Q6 -> Curaçao | I8: Kansas City | M8: I | N8: J | O8: K | P8: L | Q8: Equador
A9: 25/06 # 17h | B9: =Q6 -> Curaçao | E9: ✕ | H9: =Q7 -> Costa do Marfim | I9: Filadélfia
A10: 25/06 # 17h | B10: =Q8 -> Equador | E10: ✕ | H10: =Q5 -> Alemanha | I10: Nova Jersey | M10: Tudo Excel
A12: ▶ CLASSIFICAÇÃO (atualização automática)
A13: Pos | B13: Seleção | I13: J | J13: V | K13: E | L13: D | M13: GP | N13: GC | O13: SG | P13: PTS
A14: 1 | B14: {=INDEX(Q$14:Q$17,MATCH(1,AA$14:AA$17,0))} -> Alemanha | I14: {=INDEX(R$14:R$17,MATCH(1,AA$14:AA$17,0))} -> 2 | J14: {=INDEX(S$14:S$17,MATCH(1,AA$14:AA$17,0))} -> 2 | K14: {=INDEX(T$14:T$17,MATCH(1,AA$14:AA$17,0))} -> 0 | L14: {=INDEX(U$14:U$17,MATCH(1,AA$14:AA$17,0))} -> 0 | M14: {=INDEX(V$14:V$17,MATCH(1,AA$14:AA$17,0))} -> 9 | N14: {=INDEX(W$14:W$17,MATCH(1,AA$14:AA$17,0))} -> 2 | O14: {=INDEX(X$14:X$17,MATCH(1,AA$14:AA$17,0))} -> 7 | P14: {=INDEX(Y$14:Y$17,MATCH(1,AA$14:AA$17,0))} -> 6 | Q14: =Q5 -> Alemanha | R14: =((D5<>"")*( F5<>""))+((D7<>"")*( F7<>""))+((D10<>"")*( F10<>"")) -> 2 | S14: =IF(AND(D5<>"",F5<>""),IF(D5>F5,1,0),0)+IF(AND(D7<>"",F7<>""),IF(D7>F7,1,0),0)+IF(AND(D10<>"",F10<>""),IF(F10>D10,1,0),0) -> 2 | T14: =IF(AND(D5<>"",F5<>""),IF(D5=F5,1,0),0)+IF(AND(D7<>"",F7<>""),IF(D7=F7,1,0),0)+IF(AND(D10<>"",F10<>""),IF(D10=F10,1,0),0) -> 0 | U14: =IF(AND(D5<>"",F5<>""),IF(D5<F5,1,0),0)+IF(AND(D7<>"",F7<>""),IF(D7<F7,1,0),0)+IF(AND(D10<>"",F10<>""),IF(F10<D10,1,0),0) -> 0 | V14: =IF(D5="",0,D5)+IF(D7="",0,D7)+IF(F10="",0,F10) -> 9 | W14: =IF(F5="",0,F5)+IF(F7="",0,F7)+IF(D10="",0,D10) -> 2 | X14: =V14-W14 -> 7 | Y14: =S14*3+T14 -> 6 | Z14: =Y14*1000000+(X14+100)*10000+V14*100+4 -> 7070904 | AA14: =RANK(Z14,Z$14:Z$17,0) -> 1
A15: 2 | B15: {=INDEX(Q$14:Q$17,MATCH(2,AA$14:AA$17,0))} -> Costa do Marfim | I15: {=INDEX(R$14:R$17,MATCH(2,AA$14:AA$17,0))} -> 2 | J15: {=INDEX(S$14:S$17,MATCH(2,AA$14:AA$17,0))} -> 1 | K15: {=INDEX(T$14:T$17,MATCH(2,AA$14:AA$17,0))} -> 0 | L15: {=INDEX(U$14:U$17,MATCH(2,AA$14:AA$17,0))} -> 1 | M15: {=INDEX(V$14:V$17,MATCH(2,AA$14:AA$17,0))} -> 2 | N15: {=INDEX(W$14:W$17,MATCH(2,AA$14:AA$17,0))} -> 2 | O15: {=INDEX(X$14:X$17,MATCH(2,AA$14:AA$17,0))} -> 0 | P15: {=INDEX(Y$14:Y$17,MATCH(2,AA$14:AA$17,0))} -> 3 | Q15: =Q6 -> Curaçao | R15: =((D5<>"")*( F5<>""))+((D8<>"")*( F8<>""))+((D9<>"")*( F9<>"")) -> 2 | S15: =IF(AND(D5<>"",F5<>""),IF(F5>D5,1,0),0)+IF(AND(D8<>"",F8<>""),IF(F8>D8,1,0),0)+IF(AND(D9<>"",F9<>""),IF(D9>F9,1,0),0) -> 0 | T15: =IF(AND(D5<>"",F5<>""),IF(D5=F5,1,0),0)+IF(AND(D8<>"",F8<>""),IF(D8=F8,1,0),0)+IF(AND(D9<>"",F9<>""),IF(D9=F9,1,0),0) -> 1 | U15: =IF(AND(D5<>"",F5<>""),IF(F5<D5,1,0),0)+IF(AND(D8<>"",F8<>""),IF(F8<D8,1,0),0)+IF(AND(D9<>"",F9<>""),IF(D9<F9,1,0),0) -> 1 | V15: =IF(F5="",0,F5)+IF(F8="",0,F8)+IF(D9="",0,D9) -> 1 | W15: =IF(D5="",0,D5)+IF(D8="",0,D8)+IF(F9="",0,F9) -> 7 | X15: =V15-W15 -> -6 | Y15: =S15*3+T15 -> 1 | Z15: =Y15*1000000+(X15+100)*10000+V15*100+3 -> 1940103 | AA15: =RANK(Z15,Z$14:Z$17,0) -> 4
A16: 3 | B16: {=INDEX(Q$14:Q$17,MATCH(3,AA$14:AA$17,0))} -> Equador | I16: {=INDEX(R$14:R$17,MATCH(3,AA$14:AA$17,0))} -> 2 | J16: {=INDEX(S$14:S$17,MATCH(3,AA$14:AA$17,0))} -> 0 | K16: {=INDEX(T$14:T$17,MATCH(3,AA$14:AA$17,0))} -> 1 | L16: {=INDEX(U$14:U$17,MATCH(3,AA$14:AA$17,0))} -> 1 | M16: {=INDEX(V$14:V$17,MATCH(3,AA$14:AA$17,0))} -> 0 | N16: {=INDEX(W$14:W$17,MATCH(3,AA$14:AA$17,0))} -> 1 | O16: {=INDEX(X$14:X$17,MATCH(3,AA$14:AA$17,0))} -> -1 | P16: {=INDEX(Y$14:Y$17,MATCH(3,AA$14:AA$17,0))} -> 1 | Q16: =Q7 -> Costa do Marfim | R16: =((D6<>"")*( F6<>""))+((D7<>"")*( F7<>""))+((D9<>"")*( F9<>"")) -> 2 | S16: =IF(AND(D6<>"",F6<>""),IF(D6>F6,1,0),0)+IF(AND(D7<>"",F7<>""),IF(F7>D7,1,0),0)+IF(AND(D9<>"",F9<>""),IF(F9>D9,1,0),0) -> 1 | T16: =IF(AND(D6<>"",F6<>""),IF(D6=F6,1,0),0)+IF(AND(D7<>"",F7<>""),IF(D7=F7,1,0),0)+IF(AND(D9<>"",F9<>""),IF(D9=F9,1,0),0) -> 0 | U16: =IF(AND(D6<>"",F6<>""),IF(D6<F6,1,0),0)+IF(AND(D7<>"",F7<>""),IF(F7<D7,1,0),0)+IF(AND(D9<>"",F9<>""),IF(F9<D9,1,0),0) -> 1 | V16: =IF(D6="",0,D6)+IF(F7="",0,F7)+IF(F9="",0,F9) -> 2 | W16: =IF(F6="",0,F6)+IF(D7="",0,D7)+IF(D9="",0,D9) -> 2 | X16: =V16-W16 -> 0 | Y16: =S16*3+T16 -> 3 | Z16: =Y16*1000000+(X16+100)*10000+V16*100+2 -> 4000202 | AA16: =RANK(Z16,Z$14:Z$17,0) -> 2
A17: 4 | B17: {=INDEX(Q$14:Q$17,MATCH(4,AA$14:AA$17,0))} -> Curaçao | I17: {=INDEX(R$14:R$17,MATCH(4,AA$14:AA$17,0))} -> 2 | J17: {=INDEX(S$14:S$17,MATCH(4,AA$14:AA$17,0))} -> 0 | K17: {=INDEX(T$14:T$17,MATCH(4,AA$14:AA$17,0))} -> 1 | L17: {=INDEX(U$14:U$17,MATCH(4,AA$14:AA$17,0))} -> 1 | M17: {=INDEX(V$14:V$17,MATCH(4,AA$14:AA$17,0))} -> 1 | N17: {=INDEX(W$14:W$17,MATCH(4,AA$14:AA$17,0))} -> 7 | O17: {=INDEX(X$14:X$17,MATCH(4,AA$14:AA$17,0))} -> -6 | P17: {=INDEX(Y$14:Y$17,MATCH(4,AA$14:AA$17,0))} -> 1 | Q17: =Q8 -> Equador | R17: =((D6<>"")*( F6<>""))+((D8<>"")*( F8<>""))+((D10<>"")*( F10<>"")) -> 2 | S17: =IF(AND(D6<>"",F6<>""),IF(F6>D6,1,0),0)+IF(AND(D8<>"",F8<>""),IF(D8>F8,1,0),0)+IF(AND(D10<>"",F10<>""),IF(D10>F10,1,0),0) -> 0 | T17: =IF(AND(D6<>"",F6<>""),IF(D6=F6,1,0),0)+IF(AND(D8<>"",F8<>""),IF(D8=F8,1,0),0)+IF(AND(D10<>"",F10<>""),IF(D10=F10,1,0),0) -> 1 | U17: =IF(AND(D6<>"",F6<>""),IF(F6<D6,1,0),0)+IF(AND(D8<>"",F8<>""),IF(D8<F8,1,0),0)+IF(AND(D10<>"",F10<>""),IF(D10<F10,1,0),0) -> 1 | V17: =IF(F6="",0,F6)+IF(D8="",0,D8)+IF(D10="",0,D10) -> 0 | W17: =IF(D6="",0,D6)+IF(F8="",0,F8)+IF(F10="",0,F10) -> 1 | X17: =V17-W17 -> -1 | Y17: =S17*3+T17 -> 1 | Z17: =Y17*1000000+(X17+100)*10000+V17*100+1 -> 1990001 | AA17: =RANK(Z17,Z$14:Z$17,0) -> 3
A20: 🟢 1º e 2º classificados 🟡 3º colocado (pode avançar se for top-8) 🔴 Eliminado

Sheet Gr-F
A1: COPA DO MUNDO FIFA 2026 · GRUPO F
A3: ▶ JOGOS DA FASE DE GRUPOS (preencha apenas os placares em azul)
A4: Rodada | B4: Mandante | D4: GD | F4: GV | H4: Visitante | I4: Local
A5: 14/06 # 17h | B5: =Q5 -> Holanda | D5: 2 | E5: ✕ | F5: 2 | H5: =Q6 -> Japão | I5: Dallas | M5: NAVEGUE PELOS GRUPOS | Q5: Holanda
A6: 14/06 # 23h | B6: =Q7 -> Suécia | D6: 5 | E6: ✕ | F6: 1 | H6: =Q8 -> Tunísia | I6: Monterrey | M6: A | N6: B | O6: C | P6: D | Q6: Japão
A7: 20/06 # 14h | B7: =Q5 -> Holanda | D7: 5 | E7: ✕ | F7: 1 | H7: =Q7 -> Suécia | I7: Houston | M7: E | N7: F | O7: G | P7: H | Q7: Suécia
A8: 21/06 # 01h | B8: =Q8 -> Tunísia | D8: 0 | E8: ✕ | F8: 4 | H8: =Q6 -> Japão | I8: Monterrey | M8: I | N8: J | O8: K | P8: L | Q8: Tunísia
A9: 25/06 # 20h | B9: =Q6 -> Japão | E9: ✕ | H9: =Q7 -> Suécia | I9: Dallas
A10: 25/06 # 20h | B10: =Q8 -> Tunísia | E10: ✕ | H10: =Q5 -> Holanda | I10: Kansas City | M10: Tudo Excel
A12: ▶ CLASSIFICAÇÃO (atualização automática)
A13: Pos | B13: Seleção | I13: J | J13: V | K13: E | L13: D | M13: GP | N13: GC | O13: SG | P13: PTS
A14: 1 | B14: {=INDEX(Q$14:Q$17,MATCH(1,AA$14:AA$17,0))} -> Holanda | I14: {=INDEX(R$14:R$17,MATCH(1,AA$14:AA$17,0))} -> 2 | J14: {=INDEX(S$14:S$17,MATCH(1,AA$14:AA$17,0))} -> 1 | K14: {=INDEX(T$14:T$17,MATCH(1,AA$14:AA$17,0))} -> 1 | L14: {=INDEX(U$14:U$17,MATCH(1,AA$14:AA$17,0))} -> 0 | M14: {=INDEX(V$14:V$17,MATCH(1,AA$14:AA$17,0))} -> 7 | N14: {=INDEX(W$14:W$17,MATCH(1,AA$14:AA$17,0))} -> 3 | O14: {=INDEX(X$14:X$17,MATCH(1,AA$14:AA$17,0))} -> 4 | P14: {=INDEX(Y$14:Y$17,MATCH(1,AA$14:AA$17,0))} -> 4 | Q14: =Q5 -> Holanda | R14: =((D5<>"")*( F5<>""))+((D7<>"")*( F7<>""))+((D10<>"")*( F10<>"")) -> 2 | S14: =IF(AND(D5<>"",F5<>""),IF(D5>F5,1,0),0)+IF(AND(D7<>"",F7<>""),IF(D7>F7,1,0),0)+IF(AND(D10<>"",F10<>""),IF(F10>D10,1,0),0) -> 1 | T14: =IF(AND(D5<>"",F5<>""),IF(D5=F5,1,0),0)+IF(AND(D7<>"",F7<>""),IF(D7=F7,1,0),0)+IF(AND(D10<>"",F10<>""),IF(D10=F10,1,0),0) -> 1 | U14: =IF(AND(D5<>"",F5<>""),IF(D5<F5,1,0),0)+IF(AND(D7<>"",F7<>""),IF(D7<F7,1,0),0)+IF(AND(D10<>"",F10<>""),IF(F10<D10,1,0),0) -> 0 | V14: =IF(D5="",0,D5)+IF(D7="",0,D7)+IF(F10="",0,F10) -> 7 | W14: =IF(F5="",0,F5)+IF(F7="",0,F7)+IF(D10="",0,D10) -> 3 | X14: =V14-W14 -> 4 | Y14: =S14*3+T14 -> 4 | Z14: =Y14*1000000+(X14+100)*10000+V14*100+4 -> 5040704 | AA14: =RANK(Z14,Z$14:Z$17,0) -> 1
A15: 2 | B15: {=INDEX(Q$14:Q$17,MATCH(2,AA$14:AA$17,0))} -> Japão | I15: {=INDEX(R$14:R$17,MATCH(2,AA$14:AA$17,0))} -> 2 | J15: {=INDEX(S$14:S$17,MATCH(2,AA$14:AA$17,0))} -> 1 | K15: {=INDEX(T$14:T$17,MATCH(2,AA$14:AA$17,0))} -> 1 | L15: {=INDEX(U$14:U$17,MATCH(2,AA$14:AA$17,0))} -> 0 | M15: {=INDEX(V$14:V$17,MATCH(2,AA$14:AA$17,0))} -> 6 | N15: {=INDEX(W$14:W$17,MATCH(2,AA$14:AA$17,0))} -> 2 | O15: {=INDEX(X$14:X$17,MATCH(2,AA$14:AA$17,0))} -> 4 | P15: {=INDEX(Y$14:Y$17,MATCH(2,AA$14:AA$17,0))} -> 4 | Q15: =Q6 -> Japão | R15: =((D5<>"")*( F5<>""))+((D8<>"")*( F8<>""))+((D9<>"")*( F9<>"")) -> 2 | S15: =IF(AND(D5<>"",F5<>""),IF(F5>D5,1,0),0)+IF(AND(D8<>"",F8<>""),IF(F8>D8,1,0),0)+IF(AND(D9<>"",F9<>""),IF(D9>F9,1,0),0) -> 1 | T15: =IF(AND(D5<>"",F5<>""),IF(D5=F5,1,0),0)+IF(AND(D8<>"",F8<>""),IF(D8=F8,1,0),0)+IF(AND(D9<>"",F9<>""),IF(D9=F9,1,0),0) -> 1 | U15: =IF(AND(D5<>"",F5<>""),IF(F5<D5,1,0),0)+IF(AND(D8<>"",F8<>""),IF(F8<D8,1,0),0)+IF(AND(D9<>"",F9<>""),IF(D9<F9,1,0),0) -> 0 | V15: =IF(F5="",0,F5)+IF(F8="",0,F8)+IF(D9="",0,D9) -> 6 | W15: =IF(D5="",0,D5)+IF(D8="",0,D8)+IF(F9="",0,F9) -> 2 | X15: =V15-W15 -> 4 | Y15: =S15*3+T15 -> 4 | Z15: =Y15*1000000+(X15+100)*10000+V15*100+3 -> 5040603 | AA15: =RANK(Z15,Z$14:Z$17,0) -> 2
A16: 3 | B16: {=INDEX(Q$14:Q$17,MATCH(3,AA$14:AA$17,0))} -> Suécia | I16: {=INDEX(R$14:R$17,MATCH(3,AA$14:AA$17,0))} -> 2 | J16: {=INDEX(S$14:S$17,MATCH(3,AA$14:AA$17,0))} -> 1 | K16: {=INDEX(T$14:T$17,MATCH(3,AA$14:AA$17,0))} -> 0 | L16: {=INDEX(U$14:U$17,MATCH(3,AA$14:AA$17,0))} -> 1 | M16: {=INDEX(V$14:V$17,MATCH(3,AA$14:AA$17,0))} -> 6 | N16: {=INDEX(W$14:W$17,MATCH(3,AA$14:AA$17,0))} -> 6 | O16: {=INDEX(X$14:X$17,MATCH(3,AA$14:AA$17,0))} -> 0 | P16: {=INDEX(Y$14:Y$17,MATCH(3,AA$14:AA$17,0))} -> 3 | Q16: =Q7 -> Suécia | R16: =((D6<>"")*( F6<>""))+((D7<>"")*( F7<>""))+((D9<>"")*( F9<>"")) -> 2 | S16: =IF(AND(D6<>"",F6<>""),IF(D6>F6,1,0),0)+IF(AND(D7<>"",F7<>""),IF(F7>D7,1,0),0)+IF(AND(D9<>"",F9<>""),IF(F9>D9,1,0),0) -> 1 | T16: =IF(AND(D6<>"",F6<>""),IF(D6=F6,1,0),0)+IF(AND(D7<>"",F7<>""),IF(D7=F7,1,0),0)+IF(AND(D9<>"",F9<>""),IF(D9=F9,1,0),0) -> 0 | U16: =IF(AND(D6<>"",F6<>""),IF(D6<F6,1,0),0)+IF(AND(D7<>"",F7<>""),IF(F7<D7,1,0),0)+IF(AND(D9<>"",F9<>""),IF(F9<D9,1,0),0) -> 1 | V16: =IF(D6="",0,D6)+IF(F7="",0,F7)+IF(F9="",0,F9) -> 6 | W16: =IF(F6="",0,F6)+IF(D7="",0,D7)+IF(D9="",0,D9) -> 6 | X16: =V16-W16 -> 0 | Y16: =S16*3+T16 -> 3 | Z16: =Y16*1000000+(X16+100)*10000+V16*100+2 -> 4000602 | AA16: =RANK(Z16,Z$14:Z$17,0) -> 3
A17: 4 | B17: {=INDEX(Q$14:Q$17,MATCH(4,AA$14:AA$17,0))} -> Tunísia | I17: {=INDEX(R$14:R$17,MATCH(4,AA$14:AA$17,0))} -> 2 | J17: {=INDEX(S$14:S$17,MATCH(4,AA$14:AA$17,0))} -> 0 | K17: {=INDEX(T$14:T$17,MATCH(4,AA$14:AA$17,0))} -> 0 | L17: {=INDEX(U$14:U$17,MATCH(4,AA$14:AA$17,0))} -> 2 | M17: {=INDEX(V$14:V$17,MATCH(4,AA$14:AA$17,0))} -> 1 | N17: {=INDEX(W$14:W$17,MATCH(4,AA$14:AA$17,0))} -> 9 | O17: {=INDEX(X$14:X$17,MATCH(4,AA$14:AA$17,0))} -> -8 | P17: {=INDEX(Y$14:Y$17,MATCH(4,AA$14:AA$17,0))} -> 0 | Q17: =Q8 -> Tunísia | R17: =((D6<>"")*( F6<>""))+((D8<>"")*( F8<>""))+((D10<>"")*( F10<>"")) -> 2 | S17: =IF(AND(D6<>"",F6<>""),IF(F6>D6,1,0),0)+IF(AND(D8<>"",F8<>""),IF(D8>F8,1,0),0)+IF(AND(D10<>"",F10<>""),IF(D10>F10,1,0),0) -> 0 | T17: =IF(AND(D6<>"",F6<>""),IF(D6=F6,1,0),0)+IF(AND(D8<>"",F8<>""),IF(D8=F8,1,0),0)+IF(AND(D10<>"",F10<>""),IF(D10=F10,1,0),0) -> 0 | U17: =IF(AND(D6<>"",F6<>""),IF(F6<D6,1,0),0)+IF(AND(D8<>"",F8<>""),IF(D8<F8,1,0),0)+IF(AND(D10<>"",F10<>""),IF(D10<F10,1,0),0) -> 2 | V17: =IF(F6="",0,F6)+IF(D8="",0,D8)+IF(D10="",0,D10) -> 1 | W17: =IF(D6="",0,D6)+IF(F8="",0,F8)+IF(F10="",0,F10) -> 9 | X17: =V17-W17 -> -8 | Y17: =S17*3+T17 -> 0 | Z17: =Y17*1000000+(X17+100)*10000+V17*100+1 -> 920101 | AA17: =RANK(Z17,Z$14:Z$17,0) -> 4
A20: 🟢 1º e 2º classificados 🟡 3º colocado (pode avançar se for top-8) 🔴 Eliminado

Sheet Gr-G
A1: COPA DO MUNDO FIFA 2026 · GRUPO G
A3: ▶ JOGOS DA FASE DE GRUPOS (preencha apenas os placares em azul)
A4: Rodada | B4: Mandante | D4: GD | F4: GV | H4: Visitante | I4: Local
A5: 15/06 # 16h | B5: =Q5 -> Bélgica | D5: 1 | E5: ✕ | F5: 1 | H5: =Q6 -> Egito | I5: Seattle Field | M5: NAVEGUE PELOS GRUPOS | Q5: Bélgica
A6: 15/06 # 22h | B6: =Q7 -> Irã | D6: 2 | E6: ✕ | F6: 2 | H6: =Q8 -> Nova Zelândia | I6: Los Angeles | M6: A | N6: B | O6: C | P6: D | Q6: Egito
A7: 21/06 # 16h | B7: =Q5 -> Bélgica | D7: 0 | E7: ✕ | F7: 0 | H7: =Q7 -> Irã | I7: Los Angeles | M7: E | N7: F | O7: G | P7: H | Q7: Irã
A8: 21/06 # 22h | B8: =Q8 -> Nova Zelândia | D8: 1 | E8: ✕ | F8: 3 | H8: =Q6 -> Egito | I8: Vancouver | M8: I | N8: J | O8: K | P8: L | Q8: Nova Zelândia
A9: 27/06 # 00h | B9: =Q6 -> Egito | E9: ✕ | H9: =Q7 -> Irã | I9: Seattle
A10: 27/06 # 00h | B10: =Q8 -> Nova Zelândia | E10: ✕ | H10: =Q5 -> Bélgica | I10: Vancouver | M10: Tudo Excel
A12: ▶ CLASSIFICAÇÃO (atualização automática)
A13: Pos | B13: Seleção | I13: J | J13: V | K13: E | L13: D | M13: GP | N13: GC | O13: SG | P13: PTS
A14: 1 | B14: {=INDEX(Q$14:Q$17,MATCH(1,AA$14:AA$17,0))} -> Egito | I14: {=INDEX(R$14:R$17,MATCH(1,AA$14:AA$17,0))} -> 2 | J14: {=INDEX(S$14:S$17,MATCH(1,AA$14:AA$17,0))} -> 1 | K14: {=INDEX(T$14:T$17,MATCH(1,AA$14:AA$17,0))} -> 1 | L14: {=INDEX(U$14:U$17,MATCH(1,AA$14:AA$17,0))} -> 0 | M14: {=INDEX(V$14:V$17,MATCH(1,AA$14:AA$17,0))} -> 4 | N14: {=INDEX(W$14:W$17,MATCH(1,AA$14:AA$17,0))} -> 2 | O14: {=INDEX(X$14:X$17,MATCH(1,AA$14:AA$17,0))} -> 2 | P14: {=INDEX(Y$14:Y$17,MATCH(1,AA$14:AA$17,0))} -> 4 | Q14: =Q5 -> Bélgica | R14: =((D5<>"")*( F5<>""))+((D7<>"")*( F7<>""))+((D10<>"")*( F10<>"")) -> 2 | S14: =IF(AND(D5<>"",F5<>""),IF(D5>F5,1,0),0)+IF(AND(D7<>"",F7<>""),IF(D7>F7,1,0),0)+IF(AND(D10<>"",F10<>""),IF(F10>D10,1,0),0) -> 0 | T14: =IF(AND(D5<>"",F5<>""),IF(D5=F5,1,0),0)+IF(AND(D7<>"",F7<>""),IF(D7=F7,1,0),0)+IF(AND(D10<>"",F10<>""),IF(D10=F10,1,0),0) -> 2 | U14: =IF(AND(D5<>"",F5<>""),IF(D5<F5,1,0),0)+IF(AND(D7<>"",F7<>""),IF(D7<F7,1,0),0)+IF(AND(D10<>"",F10<>""),IF(F10<D10,1,0),0) -> 0 | V14: =IF(D5="",0,D5)+IF(D7="",0,D7)+IF(F10="",0,F10) -> 1 | W14: =IF(F5="",0,F5)+IF(F7="",0,F7)+IF(D10="",0,D10) -> 1 | X14: =V14-W14 -> 0 | Y14: =S14*3+T14 -> 2 | Z14: =Y14*1000000+(X14+100)*10000+V14*100+4 -> 3000104 | AA14: =RANK(Z14,Z$14:Z$17,0) -> 3
A15: 2 | B15: {=INDEX(Q$14:Q$17,MATCH(2,AA$14:AA$17,0))} -> Irã | I15: {=INDEX(R$14:R$17,MATCH(2,AA$14:AA$17,0))} -> 2 | J15: {=INDEX(S$14:S$17,MATCH(2,AA$14:AA$17,0))} -> 0 | K15: {=INDEX(T$14:T$17,MATCH(2,AA$14:AA$17,0))} -> 2 | L15: {=INDEX(U$14:U$17,MATCH(2,AA$14:AA$17,0))} -> 0 | M15: {=INDEX(V$14:V$17,MATCH(2,AA$14:AA$17,0))} -> 2 | N15: {=INDEX(W$14:W$17,MATCH(2,AA$14:AA$17,0))} -> 2 | O15: {=INDEX(X$14:X$17,MATCH(2,AA$14:AA$17,0))} -> 0 | P15: {=INDEX(Y$14:Y$17,MATCH(2,AA$14:AA$17,0))} -> 2 | Q15: =Q6 -> Egito | R15: =((D5<>"")*( F5<>""))+((D8<>"")*( F8<>""))+((D9<>"")*( F9<>"")) -> 2 | S15: =IF(AND(D5<>"",F5<>""),IF(F5>D5,1,0),0)+IF(AND(D8<>"",F8<>""),IF(F8>D8,1,0),0)+IF(AND(D9<>"",F9<>""),IF(D9>F9,1,0),0) -> 1 | T15: =IF(AND(D5<>"",F5<>""),IF(D5=F5,1,0),0)+IF(AND(D8<>"",F8<>""),IF(D8=F8,1,0),0)+IF(AND(D9<>"",F9<>""),IF(D9=F9,1,0),0) -> 1 | U15: =IF(AND(D5<>"",F5<>""),IF(F5<D5,1,0),0)+IF(AND(D8<>"",F8<>""),IF(F8<D8,1,0),0)+IF(AND(D9<>"",F9<>""),IF(D9<F9,1,0),0) -> 0 | V15: =IF(F5="",0,F5)+IF(F8="",0,F8)+IF(D9="",0,D9) -> 4 | W15: =IF(D5="",0,D5)+IF(D8="",0,D8)+IF(F9="",0,F9) -> 2 | X15: =V15-W15 -> 2 | Y15: =S15*3+T15 -> 4 | Z15: =Y15*1000000+(X15+100)*10000+V15*100+3 -> 5020403 | AA15: =RANK(Z15,Z$14:Z$17,0) -> 1
A16: 3 | B16: {=INDEX(Q$14:Q$17,MATCH(3,AA$14:AA$17,0))} -> Bélgica | I16: {=INDEX(R$14:R$17,MATCH(3,AA$14:AA$17,0))} -> 2 | J16: {=INDEX(S$14:S$17,MATCH(3,AA$14:AA$17,0))} -> 0 | K16: {=INDEX(T$14:T$17,MATCH(3,AA$14:AA$17,0))} -> 2 | L16: {=INDEX(U$14:U$17,MATCH(3,AA$14:AA$17,0))} -> 0 | M16: {=INDEX(V$14:V$17,MATCH(3,AA$14:AA$17,0))} -> 1 | N16: {=INDEX(W$14:W$17,MATCH(3,AA$14:AA$17,0))} -> 1 | O16: {=INDEX(X$14:X$17,MATCH(3,AA$14:AA$17,0))} -> 0 | P16: {=INDEX(Y$14:Y$17,MATCH(3,AA$14:AA$17,0))} -> 2 | Q16: =Q7 -> Irã | R16: =((D6<>"")*( F6<>""))+((D7<>"")*( F7<>""))+((D9<>"")*( F9<>"")) -> 2 | S16: =IF(AND(D6<>"",F6<>""),IF(D6>F6,1,0),0)+IF(AND(D7<>"",F7<>""),IF(F7>D7,1,0),0)+IF(AND(D9<>"",F9<>""),IF(F9>D9,1,0),0) -> 0 | T16: =IF(AND(D6<>"",F6<>""),IF(D6=F6,1,0),0)+IF(AND(D7<>"",F7<>""),IF(D7=F7,1,0),0)+IF(AND(D9<>"",F9<>""),IF(D9=F9,1,0),0) -> 2 | U16: =IF(AND(D6<>"",F6<>""),IF(D6<F6,1,0),0)+IF(AND(D7<>"",F7<>""),IF(F7<D7,1,0),0)+IF(AND(D9<>"",F9<>""),IF(F9<D9,1,0),0) -> 0 | V16: =IF(D6="",0,D6)+IF(F7="",0,F7)+IF(F9="",0,F9) -> 2 | W16: =IF(F6="",0,F6)+IF(D7="",0,D7)+IF(D9="",0,D9) -> 2 | X16: =V16-W16 -> 0 | Y16: =S16*3+T16 -> 2 | Z16: =Y16*1000000+(X16+100)*10000+V16*100+2 -> 3000202 | AA16: =RANK(Z16,Z$14:Z$17,0) -> 2
A17: 4 | B17: {=INDEX(Q$14:Q$17,MATCH(4,AA$14:AA$17,0))} -> Nova Zelândia | I17: {=INDEX(R$14:R$17,MATCH(4,AA$14:AA$17,0))} -> 2 | J17: {=INDEX(S$14:S$17,MATCH(4,AA$14:AA$17,0))} -> 0 | K17: {=INDEX(T$14:T$17,MATCH(4,AA$14:AA$17,0))} -> 1 | L17: {=INDEX(U$14:U$17,MATCH(4,AA$14:AA$17,0))} -> 1 | M17: {=INDEX(V$14:V$17,MATCH(4,AA$14:AA$17,0))} -> 3 | N17: {=INDEX(W$14:W$17,MATCH(4,AA$14:AA$17,0))} -> 5 | O17: {=INDEX(X$14:X$17,MATCH(4,AA$14:AA$17,0))} -> -2 | P17: {=INDEX(Y$14:Y$17,MATCH(4,AA$14:AA$17,0))} -> 1 | Q17: =Q8 -> Nova Zelândia | R17: =((D6<>"")*( F6<>""))+((D8<>"")*( F8<>""))+((D10<>"")*( F10<>"")) -> 2 | S17: =IF(AND(D6<>"",F6<>""),IF(F6>D6,1,0),0)+IF(AND(D8<>"",F8<>""),IF(D8>F8,1,0),0)+IF(AND(D10<>"",F10<>""),IF(D10>F10,1,0),0) -> 0 | T17: =IF(AND(D6<>"",F6<>""),IF(D6=F6,1,0),0)+IF(AND(D8<>"",F8<>""),IF(D8=F8,1,0),0)+IF(AND(D10<>"",F10<>""),IF(D10=F10,1,0),0) -> 1 | U17: =IF(AND(D6<>"",F6<>""),IF(F6<D6,1,0),0)+IF(AND(D8<>"",F8<>""),IF(D8<F8,1,0),0)+IF(AND(D10<>"",F10<>""),IF(D10<F10,1,0),0) -> 1 | V17: =IF(F6="",0,F6)+IF(D8="",0,D8)+IF(D10="",0,D10) -> 3 | W17: =IF(D6="",0,D6)+IF(F8="",0,F8)+IF(F10="",0,F10) -> 5 | X17: =V17-W17 -> -2 | Y17: =S17*3+T17 -> 1 | Z17: =Y17*1000000+(X17+100)*10000+V17*100+1 -> 1980301 | AA17: =RANK(Z17,Z$14:Z$17,0) -> 4
A20: 🟢 1º e 2º classificados 🟡 3º colocado (pode avançar se for top-8) 🔴 Eliminado

Sheet Gr-H
A1: COPA DO MUNDO FIFA 2026 · GRUPO H
A3: ▶ JOGOS DA FASE DE GRUPOS (preencha apenas os placares em azul)
A4: Rodada | B4: Mandante | D4: GD | F4: GV | H4: Visitante | I4: Local
A5: 15/06 # 13h | B5: =Q5 -> Espanha | D5: 0 | E5: ✕ | F5: 0 | H5: =Q6 -> Cabo Verde | I5: Atlanta | M5: NAVEGUE PELOS GRUPOS | Q5: Espanha
A6: 15/06 # 19h | B6: =Q7 -> Arábia Saudita | D6: 1 | E6: ✕ | F6: 1 | H6: =Q8 -> Uruguai | I6: Miami | M6: A | N6: B | O6: C | P6: D | Q6: Cabo Verde
A7: 21/06 # 13h | B7: =Q5 -> Espanha | D7: 4 | E7: ✕ | F7: 0 | H7: =Q7 -> Arábia Saudita | I7: Atlanta | M7: E | N7: F | O7: G | P7: H | Q7: Arábia Saudita
A8: 21/06 # 19h | B8: =Q8 -> Uruguai | D8: 2 | E8: ✕ | F8: 2 | H8: =Q6 -> Cabo Verde | I8: Miami | M8: I | N8: J | O8: K | P8: L | Q8: Uruguai
A9: 26/06 # 21h | B9: =Q6 -> Cabo Verde | E9: ✕ | H9: =Q7 -> Arábia Saudita | I9: Houston
A10: 26/06 # 21h | B10: =Q8 -> Uruguai | E10: ✕ | H10: =Q5 -> Espanha | I10: Guadalajara | M10: Tudo Excel
A12: ▶ CLASSIFICAÇÃO (atualização automática)
A13: Pos | B13: Seleção | I13: J | J13: V | K13: E | L13: D | M13: GP | N13: GC | O13: SG | P13: PTS
A14: 1 | B14: {=INDEX(Q$14:Q$17,MATCH(1,AA$14:AA$17,0))} -> Espanha | I14: {=INDEX(R$14:R$17,MATCH(1,AA$14:AA$17,0))} -> 2 | J14: {=INDEX(S$14:S$17,MATCH(1,AA$14:AA$17,0))} -> 1 | K14: {=INDEX(T$14:T$17,MATCH(1,AA$14:AA$17,0))} -> 1 | L14: {=INDEX(U$14:U$17,MATCH(1,AA$14:AA$17,0))} -> 0 | M14: {=INDEX(V$14:V$17,MATCH(1,AA$14:AA$17,0))} -> 4 | N14: {=INDEX(W$14:W$17,MATCH(1,AA$14:AA$17,0))} -> 0 | O14: {=INDEX(X$14:X$17,MATCH(1,AA$14:AA$17,0))} -> 4 | P14: {=INDEX(Y$14:Y$17,MATCH(1,AA$14:AA$17,0))} -> 4 | Q14: =Q5 -> Espanha | R14: =((D5<>"")*( F5<>""))+((D7<>"")*( F7<>""))+((D10<>"")*( F10<>"")) -> 2 | S14: =IF(AND(D5<>"",F5<>""),IF(D5>F5,1,0),0)+IF(AND(D7<>"",F7<>""),IF(D7>F7,1,0),0)+IF(AND(D10<>"",F10<>""),IF(F10>D10,1,0),0) -> 1 | T14: =IF(AND(D5<>"",F5<>""),IF(D5=F5,1,0),0)+IF(AND(D7<>"",F7<>""),IF(D7=F7,1,0),0)+IF(AND(D10<>"",F10<>""),IF(D10=F10,1,0),0) -> 1 | U14: =IF(AND(D5<>"",F5<>""),IF(D5<F5,1,0),0)+IF(AND(D7<>"",F7<>""),IF(D7<F7,1,0),0)+IF(AND(D10<>"",F10<>""),IF(F10<D10,1,0),0) -> 0 | V14: =IF(D5="",0,D5)+IF(D7="",0,D7)+IF(F10="",0,F10) -> 4 | W14: =IF(F5="",0,F5)+IF(F7="",0,F7)+IF(D10="",0,D10) -> 0 | X14: =V14-W14 -> 4 | Y14: =S14*3+T14 -> 4 | Z14: =Y14*1000000+(X14+100)*10000+V14*100+4 -> 5040404 | AA14: =RANK(Z14,Z$14:Z$17,0) -> 1
A15: 2 | B15: {=INDEX(Q$14:Q$17,MATCH(2,AA$14:AA$17,0))} -> Uruguai | I15: {=INDEX(R$14:R$17,MATCH(2,AA$14:AA$17,0))} -> 2 | J15: {=INDEX(S$14:S$17,MATCH(2,AA$14:AA$17,0))} -> 0 | K15: {=INDEX(T$14:T$17,MATCH(2,AA$14:AA$17,0))} -> 2 | L15: {=INDEX(U$14:U$17,MATCH(2,AA$14:AA$17,0))} -> 0 | M15: {=INDEX(V$14:V$17,MATCH(2,AA$14:AA$17,0))} -> 3 | N15: {=INDEX(W$14:W$17,MATCH(2,AA$14:AA$17,0))} -> 3 | O15: {=INDEX(X$14:X$17,MATCH(2,AA$14:AA$17,0))} -> 0 | P15: {=INDEX(Y$14:Y$17,MATCH(2,AA$14:AA$17,0))} -> 2 | Q15: =Q6 -> Cabo Verde | R15: =((D5<>"")*( F5<>""))+((D8<>"")*( F8<>""))+((D9<>"")*( F9<>"")) -> 2 | S15: =IF(AND(D5<>"",F5<>""),IF(F5>D5,1,0),0)+IF(AND(D8<>"",F8<>""),IF(F8>D8,1,0),0)+IF(AND(D9<>"",F9<>""),IF(D9>F9,1,0),0) -> 0 | T15: =IF(AND(D5<>"",F5<>""),IF(D5=F5,1,0),0)+IF(AND(D8<>"",F8<>""),IF(D8=F8,1,0),0)+IF(AND(D9<>"",F9<>""),IF(D9=F9,1,0),0) -> 2 | U15: =IF(AND(D5<>"",F5<>""),IF(F5<D5,1,0),0)+IF(AND(D8<>"",F8<>""),IF(F8<D8,1,0),0)+IF(AND(D9<>"",F9<>""),IF(D9<F9,1,0),0) -> 0 | V15: =IF(F5="",0,F5)+IF(F8="",0,F8)+IF(D9="",0,D9) -> 2 | W15: =IF(D5="",0,D5)+IF(D8="",0,D8)+IF(F9="",0,F9) -> 2 | X15: =V15-W15 -> 0 | Y15: =S15*3+T15 -> 2 | Z15: =Y15*1000000+(X15+100)*10000+V15*100+3 -> 3000203 | AA15: =RANK(Z15,Z$14:Z$17,0) -> 3
A16: 3 | B16: {=INDEX(Q$14:Q$17,MATCH(3,AA$14:AA$17,0))} -> Cabo Verde | I16: {=INDEX(R$14:R$17,MATCH(3,AA$14:AA$17,0))} -> 2 | J16: {=INDEX(S$14:S$17,MATCH(3,AA$14:AA$17,0))} -> 0 | K16: {=INDEX(T$14:T$17,MATCH(3,AA$14:AA$17,0))} -> 2 | L16: {=INDEX(U$14:U$17,MATCH(3,AA$14:AA$17,0))} -> 0 | M16: {=INDEX(V$14:V$17,MATCH(3,AA$14:AA$17,0))} -> 2 | N16: {=INDEX(W$14:W$17,MATCH(3,AA$14:AA$17,0))} -> 2 | O16: {=INDEX(X$14:X$17,MATCH(3,AA$14:AA$17,0))} -> 0 | P16: {=INDEX(Y$14:Y$17,MATCH(3,AA$14:AA$17,0))} -> 2 | Q16: =Q7 -> Arábia Saudita | R16: =((D6<>"")*( F6<>""))+((D7<>"")*( F7<>""))+((D9<>"")*( F9<>"")) -> 2 | S16: =IF(AND(D6<>"",F6<>""),IF(D6>F6,1,0),0)+IF(AND(D7<>"",F7<>""),IF(F7>D7,1,0),0)+IF(AND(D9<>"",F9<>""),IF(F9>D9,1,0),0) -> 0 | T16: =IF(AND(D6<>"",F6<>""),IF(D6=F6,1,0),0)+IF(AND(D7<>"",F7<>""),IF(D7=F7,1,0),0)+IF(AND(D9<>"",F9<>""),IF(D9=F9,1,0),0) -> 1 | U16: =IF(AND(D6<>"",F6<>""),IF(D6<F6,1,0),0)+IF(AND(D7<>"",F7<>""),IF(F7<D7,1,0),0)+IF(AND(D9<>"",F9<>""),IF(F9<D9,1,0),0) -> 1 | V16: =IF(D6="",0,D6)+IF(F7="",0,F7)+IF(F9="",0,F9) -> 1 | W16: =IF(F6="",0,F6)+IF(D7="",0,D7)+IF(D9="",0,D9) -> 5 | X16: =V16-W16 -> -4 | Y16: =S16*3+T16 -> 1 | Z16: =Y16*1000000+(X16+100)*10000+V16*100+2 -> 1960102 | AA16: =RANK(Z16,Z$14:Z$17,0) -> 4
A17: 4 | B17: {=INDEX(Q$14:Q$17,MATCH(4,AA$14:AA$17,0))} -> Arábia Saudita | I17: {=INDEX(R$14:R$17,MATCH(4,AA$14:AA$17,0))} -> 2 | J17: {=INDEX(S$14:S$17,MATCH(4,AA$14:AA$17,0))} -> 0 | K17: {=INDEX(T$14:T$17,MATCH(4,AA$14:AA$17,0))} -> 1 | L17: {=INDEX(U$14:U$17,MATCH(4,AA$14:AA$17,0))} -> 1 | M17: {=INDEX(V$14:V$17,MATCH(4,AA$14:AA$17,0))} -> 1 | N17: {=INDEX(W$14:W$17,MATCH(4,AA$14:AA$17,0))} -> 5 | O17: {=INDEX(X$14:X$17,MATCH(4,AA$14:AA$17,0))} -> -4 | P17: {=INDEX(Y$14:Y$17,MATCH(4,AA$14:AA$17,0))} -> 1 | Q17: =Q8 -> Uruguai | R17: =((D6<>"")*( F6<>""))+((D8<>"")*( F8<>""))+((D10<>"")*( F10<>"")) -> 2 | S17: =IF(AND(D6<>"",F6<>""),IF(F6>D6,1,0),0)+IF(AND(D8<>"",F8<>""),IF(D8>F8,1,0),0)+IF(AND(D10<>"",F10<>""),IF(D10>F10,1,0),0) -> 0 | T17: =IF(AND(D6<>"",F6<>""),IF(D6=F6,1,0),0)+IF(AND(D8<>"",F8<>""),IF(D8=F8,1,0),0)+IF(AND(D10<>"",F10<>""),IF(D10=F10,1,0),0) -> 2 | U17: =IF(AND(D6<>"",F6<>""),IF(F6<D6,1,0),0)+IF(AND(D8<>"",F8<>""),IF(D8<F8,1,0),0)+IF(AND(D10<>"",F10<>""),IF(D10<F10,1,0),0) -> 0 | V17: =IF(F6="",0,F6)+IF(D8="",0,D8)+IF(D10="",0,D10) -> 3 | W17: =IF(D6="",0,D6)+IF(F8="",0,F8)+IF(F10="",0,F10) -> 3 | X17: =V17-W17 -> 0 | Y17: =S17*3+T17 -> 2 | Z17: =Y17*1000000+(X17+100)*10000+V17*100+1 -> 3000301 | AA17: =RANK(Z17,Z$14:Z$17,0) -> 2
A20: 🟢 1º e 2º classificados 🟡 3º colocado (pode avançar se for top-8) 🔴 Eliminado

Sheet Gr-I
A1: COPA DO MUNDO FIFA 2026 · GRUPO I
A3: ▶ JOGOS DA FASE DE GRUPOS (preencha apenas os placares em azul)
A4: Rodada | B4: Mandante | D4: GD | F4: GV | H4: Visitante | I4: Local
A5: 16/06 # 16h | B5: =Q5 -> França | D5: 3 | E5: ✕ | F5: 1 | H5: =Q6 -> Senegal | I5: Nova Jersey | M5: NAVEGUE PELOS GRUPOS | Q5: França
A6: 16/06 # 19h | B6: =Q7 -> Iraque | D6: 1 | E6: ✕ | F6: 4 | H6: =Q8 -> Noruega | I6: Boston | M6: A | N6: B | O6: C | P6: D | Q6: Senegal
A7: 22/06 # 18h | B7: =Q5 -> França | E7: ✕ | H7: =Q7 -> Iraque | I7: Filadélfia | M7: E | N7: F | O7: G | P7: H | Q7: Iraque
A8: 22/06 # 21h | B8: =Q8 -> Noruega | E8: ✕ | H8: =Q6 -> Senegal | I8: Nova Jersey | M8: I | N8: J | O8: K | P8: L | Q8: Noruega
A9: 26/06 # 16h | B9: =Q8 -> Noruega | E9: ✕ | H9: =Q5 -> França | I9: Boston
A10: 26/06 # 16h | B10: =Q6 -> Senegal | E10: ✕ | H10: =Q7 -> Iraque | I10: Toronto | M10: Tudo Excel
A12: ▶ CLASSIFICAÇÃO (atualização automática)
A13: Pos | B13: Seleção | I13: J | J13: V | K13: E | L13: D | M13: GP | N13: GC | O13: SG | P13: PTS
A14: 1 | B14: {=INDEX(Q$14:Q$17,MATCH(1,AA$14:AA$17,0))} -> Noruega | I14: {=INDEX(R$14:R$17,MATCH(1,AA$14:AA$17,0))} -> 1 | J14: {=INDEX(S$14:S$17,MATCH(1,AA$14:AA$17,0))} -> 1 | K14: {=INDEX(T$14:T$17,MATCH(1,AA$14:AA$17,0))} -> 0 | L14: {=INDEX(U$14:U$17,MATCH(1,AA$14:AA$17,0))} -> 0 | M14: {=INDEX(V$14:V$17,MATCH(1,AA$14:AA$17,0))} -> 4 | N14: {=INDEX(W$14:W$17,MATCH(1,AA$14:AA$17,0))} -> 1 | O14: {=INDEX(X$14:X$17,MATCH(1,AA$14:AA$17,0))} -> 3 | P14: {=INDEX(Y$14:Y$17,MATCH(1,AA$14:AA$17,0))} -> 3 | Q14: =Q5 -> França | R14: =((D5<>"")*( F5<>""))+((D7<>"")*( F7<>""))+((D9<>"")*( F9<>"")) -> 1 | S14: =IF(AND(D5<>"",F5<>""),IF(D5>F5,1,0),0)+IF(AND(D7<>"",F7<>""),IF(D7>F7,1,0),0)+IF(AND(D9<>"",F9<>""),IF(F9>D9,1,0),0) -> 1 | T14: =IF(AND(D5<>"",F5<>""),IF(D5=F5,1,0),0)+IF(AND(D7<>"",F7<>""),IF(D7=F7,1,0),0)+IF(AND(D9<>"",F9<>""),IF(D9=F9,1,0),0) -> 0 | U14: =IF(AND(D5<>"",F5<>""),IF(D5<F5,1,0),0)+IF(AND(D7<>"",F7<>""),IF(D7<F7,1,0),0)+IF(AND(D9<>"",F9<>""),IF(F9<D9,1,0),0) -> 0 | V14: =IF(D5="",0,D5)+IF(D7="",0,D7)+IF(F9="",0,F9) -> 3 | W14: =IF(F5="",0,F5)+IF(F7="",0,F7)+IF(D9="",0,D9) -> 1 | X14: =V14-W14 -> 2 | Y14: =S14*3+T14 -> 3 | Z14: =Y14*1000000+(X14+100)*10000+V14*100+4 -> 4020304 | AA14: =RANK(Z14,Z$14:Z$17,0) -> 2
A15: 2 | B15: {=INDEX(Q$14:Q$17,MATCH(2,AA$14:AA$17,0))} -> França | I15: {=INDEX(R$14:R$17,MATCH(2,AA$14:AA$17,0))} -> 1 | J15: {=INDEX(S$14:S$17,MATCH(2,AA$14:AA$17,0))} -> 1 | K15: {=INDEX(T$14:T$17,MATCH(2,AA$14:AA$17,0))} -> 0 | L15: {=INDEX(U$14:U$17,MATCH(2,AA$14:AA$17,0))} -> 0 | M15: {=INDEX(V$14:V$17,MATCH(2,AA$14:AA$17,0))} -> 3 | N15: {=INDEX(W$14:W$17,MATCH(2,AA$14:AA$17,0))} -> 1 | O15: {=INDEX(X$14:X$17,MATCH(2,AA$14:AA$17,0))} -> 2 | P15: {=INDEX(Y$14:Y$17,MATCH(2,AA$14:AA$17,0))} -> 3 | Q15: =Q6 -> Senegal | R15: =((D5<>"")*( F5<>""))+((D8<>"")*( F8<>""))+((D10<>"")*( F10<>"")) -> 1 | S15: =IF(AND(D5<>"",F5<>""),IF(F5>D5,1,0),0)+IF(AND(D8<>"",F8<>""),IF(F8>D8,1,0),0)+IF(AND(D10<>"",F10<>""),IF(D10>F10,1,0),0) -> 0 | T15: =IF(AND(D5<>"",F5<>""),IF(D5=F5,1,0),0)+IF(AND(D8<>"",F8<>""),IF(D8=F8,1,0),0)+IF(AND(D10<>"",F10<>""),IF(D10=F10,1,0),0) -> 0 | U15: =IF(AND(D5<>"",F5<>""),IF(F5<D5,1,0),0)+IF(AND(D8<>"",F8<>""),IF(F8<D8,1,0),0)+IF(AND(D10<>"",F10<>""),IF(D10<F10,1,0),0) -> 1 | V15: =IF(F5="",0,F5)+IF(F8="",0,F8)+IF(D10="",0,D10) -> 1 | W15: =IF(D5="",0,D5)+IF(D8="",0,D8)+IF(F10="",0,F10) -> 3 | X15: =V15-W15 -> -2 | Y15: =S15*3+T15 -> 0 | Z15: =Y15*1000000+(X15+100)*10000+V15*100+3 -> 980103 | AA15: =RANK(Z15,Z$14:Z$17,0) -> 3
A16: 3 | B16: {=INDEX(Q$14:Q$17,MATCH(3,AA$14:AA$17,0))} -> Senegal | I16: {=INDEX(R$14:R$17,MATCH(3,AA$14:AA$17,0))} -> 1 | J16: {=INDEX(S$14:S$17,MATCH(3,AA$14:AA$17,0))} -> 0 | K16: {=INDEX(T$14:T$17,MATCH(3,AA$14:AA$17,0))} -> 0 | L16: {=INDEX(U$14:U$17,MATCH(3,AA$14:AA$17,0))} -> 1 | M16: {=INDEX(V$14:V$17,MATCH(3,AA$14:AA$17,0))} -> 1 | N16: {=INDEX(W$14:W$17,MATCH(3,AA$14:AA$17,0))} -> 3 | O16: {=INDEX(X$14:X$17,MATCH(3,AA$14:AA$17,0))} -> -2 | P16: {=INDEX(Y$14:Y$17,MATCH(3,AA$14:AA$17,0))} -> 0 | Q16: =Q7 -> Iraque | R16: =((D6<>"")*( F6<>""))+((D7<>"")*( F7<>""))+((D10<>"")*( F10<>"")) -> 1 | S16: =IF(AND(D6<>"",F6<>""),IF(D6>F6,1,0),0)+IF(AND(D7<>"",F7<>""),IF(F7>D7,1,0),0)+IF(AND(D10<>"",F10<>""),IF(F10>D10,1,0),0) -> 0 | T16: =IF(AND(D6<>"",F6<>""),IF(D6=F6,1,0),0)+IF(AND(D7<>"",F7<>""),IF(D7=F7,1,0),0)+IF(AND(D10<>"",F10<>""),IF(D10=F10,1,0),0) -> 0 | U16: =IF(AND(D6<>"",F6<>""),IF(D6<F6,1,0),0)+IF(AND(D7<>"",F7<>""),IF(F7<D7,1,0),0)+IF(AND(D10<>"",F10<>""),IF(F10<D10,1,0),0) -> 1 | V16: =IF(D6="",0,D6)+IF(F7="",0,F7)+IF(F10="",0,F10) -> 1 | W16: =IF(F6="",0,F6)+IF(D7="",0,D7)+IF(D10="",0,D10) -> 4 | X16: =V16-W16 -> -3 | Y16: =S16*3+T16 -> 0 | Z16: =Y16*1000000+(X16+100)*10000+V16*100+2 -> 970102 | AA16: =RANK(Z16,Z$14:Z$17,0) -> 4
A17: 4 | B17: {=INDEX(Q$14:Q$17,MATCH(4,AA$14:AA$17,0))} -> Iraque | I17: {=INDEX(R$14:R$17,MATCH(4,AA$14:AA$17,0))} -> 1 | J17: {=INDEX(S$14:S$17,MATCH(4,AA$14:AA$17,0))} -> 0 | K17: {=INDEX(T$14:T$17,MATCH(4,AA$14:AA$17,0))} -> 0 | L17: {=INDEX(U$14:U$17,MATCH(4,AA$14:AA$17,0))} -> 1 | M17: {=INDEX(V$14:V$17,MATCH(4,AA$14:AA$17,0))} -> 1 | N17: {=INDEX(W$14:W$17,MATCH(4,AA$14:AA$17,0))} -> 4 | O17: {=INDEX(X$14:X$17,MATCH(4,AA$14:AA$17,0))} -> -3 | P17: {=INDEX(Y$14:Y$17,MATCH(4,AA$14:AA$17,0))} -> 0 | Q17: =Q8 -> Noruega | R17: =((D6<>"")*( F6<>""))+((D8<>"")*( F8<>""))+((D9<>"")*( F9<>"")) -> 1 | S17: =IF(AND(D6<>"",F6<>""),IF(F6>D6,1,0),0)+IF(AND(D8<>"",F8<>""),IF(D8>F8,1,0),0)+IF(AND(D9<>"",F9<>""),IF(D9>F9,1,0),0) -> 1 | T17: =IF(AND(D6<>"",F6<>""),IF(D6=F6,1,0),0)+IF(AND(D8<>"",F8<>""),IF(D8=F8,1,0),0)+IF(AND(D9<>"",F9<>""),IF(D9=F9,1,0),0) -> 0 | U17: =IF(AND(D6<>"",F6<>""),IF(F6<D6,1,0),0)+IF(AND(D8<>"",F8<>""),IF(D8<F8,1,0),0)+IF(AND(D9<>"",F9<>""),IF(D9<F9,1,0),0) -> 0 | V17: =IF(F6="",0,F6)+IF(D8="",0,D8)+IF(D9="",0,D9) -> 4 | W17: =IF(D6="",0,D6)+IF(F8="",0,F8)+IF(F9="",0,F9) -> 1 | X17: =V17-W17 -> 3 | Y17: =S17*3+T17 -> 3 | Z17: =Y17*1000000+(X17+100)*10000+V17*100+1 -> 4030401 | AA17: =RANK(Z17,Z$14:Z$17,0) -> 1
A20: 🟢 1º e 2º classificados 🟡 3º colocado (pode avançar se for top-8) 🔴 Eliminado

Sheet Gr-J
A1: COPA DO MUNDO FIFA 2026 · GRUPO J
A3: ▶ JOGOS DA FASE DE GRUPOS (preencha apenas os placares em azul)
A4: Rodada | B4: Mandante | D4: GD | F4: GV | H4: Visitante | I4: Local
A5: 16/06 # 22h | B5: =Q5 -> Argentina | D5: 3 | E5: ✕ | F5: 0 | H5: =Q6 -> Argélia | I5: Kansas City | M5: NAVEGUE PELOS GRUPOS | Q5: Argentina
A6: 17/06 # 01h | B6: =Q7 -> Áustria | D6: 3 | E6: ✕ | F6: 1 | H6: =Q8 -> Jordânia | I6: Santa Clara | M6: A | N6: B | O6: C | P6: D | Q6: Argélia
A7: 22/06 # 14h | B7: =Q5 -> Argentina | D7: 2 | E7: ✕ | F7: 0 | H7: =Q7 -> Áustria | I7: Dallas | M7: E | N7: F | O7: G | P7: H | Q7: Áustria
A8: 23/06 # 00h | B8: =Q8 -> Jordânia | E8: ✕ | H8: =Q6 -> Argélia | I8: São Francisco | M8: I | N8: J | O8: K | P8: L | Q8: Jordânia
A9: 27/06 # 23h | B9: =Q6 -> Argélia | E9: ✕ | H9: =Q7 -> Áustria | I9: Kansas City
A10: 27/06 # 23h | B10: =Q8 -> Jordânia | E10: ✕ | H10: =Q5 -> Argentina | I10: Dallas | M10: Tudo Excel
A12: ▶ CLASSIFICAÇÃO (atualização automática)
A13: Pos | B13: Seleção | I13: J | J13: V | K13: E | L13: D | M13: GP | N13: GC | O13: SG | P13: PTS
